<?xml version="1.0" encoding="utf-8"?>
<!-- This URDF was automatically created by SolidWorks to URDF Exporter! Originally created by Stephen Brawner (brawner@gmail.com) 
     Commit Version: 1.6.0-4-g7f85cfe  Build Version: 1.6.7995.38578
     For more information, please see http://wiki.ros.org/sw_urdf_exporter -->
<robot
  name="AAAckermann_for sim">
  <link
    name="base_link">
    <inertial>
      <origin
        xyz="0.378273956824531 0.207368508650551 0.267336278539194"
        rpy="0 0 0" />
      <mass
        value="5.27646497943025" />
      <inertia
        ixx="0.0446747163082627"
        ixy="-1.52872319055898E-08"
        ixz="-8.31952501961673E-09"
        iyy="0.0732375170085209"
        iyz="1.2162951389861E-07"
        izz="0.0303582217165426" />
    </inertial>
    <visual>
      <origin
        xyz="0 0 0"
        rpy="0 0 0" />
      <geometry>
        <mesh
          filename="package://AAAckermann_for sim/meshes/base_link.STL" />
      </geometry>
      <material
        name="">
        <color
          rgba="0.792156862745098 0.819607843137255 0.933333333333333 1" />
      </material>
    </visual>
    <collision>
      <origin
        xyz="0 0 0"
        rpy="0 0 0" />
      <geometry>
        <mesh
          filename="package://AAAckermann_for sim/meshes/base_link.STL" />
      </geometry>
    </collision>
  </link>
  <link
    name="front_left">
    <inertial>
      <origin
        xyz="2.7756E-17 0.025726 0"
        rpy="0 0 0" />
      <mass
        value="0.24047" />
      <inertia
        ixx="0.00024514"
        ixy="1.8023E-20"
        ixz="0"
        iyy="0.00045262"
        iyz="4.4133E-20"
        izz="0.00024514" />
    </inertial>
    <visual>
      <origin
        xyz="0 0 0"
        rpy="0 0 0" />
      <geometry>
        <mesh
          filename="package://AAAckermann_for sim/meshes/front_left.STL" />
      </geometry>
      <material
        name="">
        <color
          rgba="0.79216 0.81961 0.93333 1" />
      </material>
    </visual>
    <collision>
      <origin
        xyz="0 0 0"
        rpy="0 0 0" />
      <geometry>
        <mesh
          filename="package://AAAckermann_for sim/meshes/front_left.STL" />
      </geometry>
    </collision>
  </link>
  <joint
    name="front_left_joint"
    type="continuous">
    <origin
      xyz="0.000500000000046352 0.249850000000001 -0.0745000000001352"
      rpy="3.14159265358979 0.391796412189509 3.14159265358979" />
    <parent
      link="base_link" />
    <child
      link="front_left" />
    <axis
      xyz="0 1 0" />
  </joint>
  <link
    name="front_right">
    <inertial>
      <origin
        xyz="-1.52655665885959E-16 0.0257257525083612 2.77555756156289E-17"
        rpy="0 0 0" />
      <mass
        value="0.240470068076377" />
      <inertia
        ixx="0.000245137261047143"
        ixy="-1.9265269650864E-20"
        ixz="0"
        iyy="0.000452624182450972"
        iyz="-4.3727623063712E-20"
        izz="0.000245137261047143" />
    </inertial>
    <visual>
      <origin
        xyz="0 0 0"
        rpy="0 0 0" />
      <geometry>
        <mesh
          filename="package://AAAckermann_for sim/meshes/front_right.STL" />
      </geometry>
      <material
        name="">
        <color
          rgba="0.792156862745098 0.819607843137255 0.933333333333333 1" />
      </material>
    </visual>
    <collision>
      <origin
        xyz="0 0 0"
        rpy="0 0 0" />
      <geometry>
        <mesh
          filename="package://AAAckermann_for sim/meshes/front_right.STL" />
      </geometry>
    </collision>
  </link>
  <joint
    name="front_right_joint"
    type="continuous">
    <origin
      xyz="0.000499999999999973 -0.250150000000045 -0.0745000000001819"
      rpy="0 0.467678189791487 3.14159265358979" />
    <parent
      link="base_link" />
    <child
      link="front_right" />
    <axis
      xyz="0 1 0" />
  </joint>
  <link
    name="streeing_left">
    <inertial>
      <origin
        xyz="0.0295849565835315 0.0305517507053702 0.00025133465892857"
        rpy="0 0 0" />
      <mass
        value="0.0657716016430145" />
      <inertia
        ixx="3.3342629769735E-05"
        ixy="-6.70427737231874E-07"
        ixz="-1.64742779350747E-08"
        iyy="3.29488469439198E-05"
        iyz="-7.80535173256215E-09"
        izz="1.43678477927653E-05" />
    </inertial>
    <visual>
      <origin
        xyz="0 0 0"
        rpy="0 0 0" />
      <geometry>
        <mesh
          filename="package://AAAckermann_for sim/meshes/streeing_left.STL" />
      </geometry>
      <material
        name="">
        <color
          rgba="0.792156862745098 0.819607843137255 0.933333333333333 1" />
      </material>
    </visual>
    <collision>
      <origin
        xyz="0 0 0"
        rpy="0 0 0" />
      <geometry>
        <mesh
          filename="package://AAAckermann_for sim/meshes/streeing_left.STL" />
      </geometry>
    </collision>
  </link>
  <joint
    name="streeing_left_joint"
    type="continuous">
    <origin
      xyz="-0.468499999999953 0.19234999999993 -0.0435000000003572"
      rpy="-1.5707963267949 0 1.55489967824877" />
    <parent
      link="base_link" />
    <child
      link="streeing_left" />
    <axis
      xyz="0 1 0" />
  </joint>
  <link
    name="back_left">
    <inertial>
      <origin
        xyz="-4.44089209850063E-16 0.0283132600998284 -5.55111512312578E-17"
        rpy="0 0 0" />
      <mass
        value="0.240470068076377" />
      <inertia
        ixx="0.000245137261047143"
        ixy="-9.23054154270374E-19"
        ixz="-1.35525271560688E-20"
        iyy="0.000452624182450971"
        iyz="6.41098061953099E-19"
        izz="0.000245137261047143" />
    </inertial>
    <visual>
      <origin
        xyz="0 0 0"
        rpy="0 0 0" />
      <geometry>
        <mesh
          filename="package://AAAckermann_for sim/meshes/back_left.STL" />
      </geometry>
      <material
        name="">
        <color
          rgba="0.792156862745098 0.819607843137255 0.933333333333333 1" />
      </material>
    </visual>
    <collision>
      <origin
        xyz="0 0 0"
        rpy="0 0 0" />
      <geometry>
        <mesh
          filename="package://AAAckermann_for sim/meshes/back_left.STL" />
      </geometry>
    </collision>
  </link>
  <joint
    name="back_left_joint"
    type="continuous">
    <origin
      xyz="0.0664124924085357 0.0314999999999999 0"
      rpy="0 1.07169307776457 -1.57079632679492" />
    <parent
      link="streeing_left" />
    <child
      link="back_left" />
    <axis
      xyz="0 1 0" />
  </joint>
  <link
    name="streeing_right">
    <inertial>
      <origin
        xyz="0.0310436860976285 0.0295964978436791 0.00306609070713337"
        rpy="0 0 0" />
      <mass
        value="0.0614331768620609" />
      <inertia
        ixx="2.30324396146209E-05"
        ixy="-6.66872189933639E-07"
        ixz="2.4598292442122E-06"
        iyy="2.16156437412178E-05"
        iyz="3.18637791901642E-10"
        izz="1.32958532185453E-05" />
    </inertial>
    <visual>
      <origin
        xyz="0 0 0"
        rpy="0 0 0" />
      <geometry>
        <mesh
          filename="package://AAAckermann_for sim/meshes/streeing_right.STL" />
      </geometry>
      <material
        name="">
        <color
          rgba="0.792156862745098 0.819607843137255 0.933333333333333 1" />
      </material>
    </visual>
    <collision>
      <origin
        xyz="0 0 0"
        rpy="0 0 0" />
      <geometry>
        <mesh
          filename="package://AAAckermann_for sim/meshes/streeing_right.STL" />
      </geometry>
    </collision>
  </link>
  <joint
    name="streeing_right_joint"
    type="continuous">
    <origin
      xyz="-0.468499999999954 -0.191650000000066 -0.0435000000003106"
      rpy="-1.5707963267949 0 -1.59505698581713" />
    <parent
      link="base_link" />
    <child
      link="streeing_right" />
    <axis
      xyz="0 1 0" />
  </joint>
  <link
    name="back_right">
    <inertial>
      <origin
        xyz="-1.11022302462516E-16 0.0295015905148818 -5.55111512312578E-16"
        rpy="0 0 0" />
      <mass
        value="0.240470068076377" />
      <inertia
        ixx="0.000245137261047142"
        ixy="-3.62953617898468E-19"
        ixz="-6.7762635780344E-21"
        iyy="0.000452624182450971"
        iyz="-9.82558218814988E-20"
        izz="0.000245137261047142" />
    </inertial>
    <visual>
      <origin
        xyz="0 0 0"
        rpy="0 0 0" />
      <geometry>
        <mesh
          filename="package://AAAckermann_for sim/meshes/back_right.STL" />
      </geometry>
      <material
        name="">
        <color
          rgba="0.792156862745098 0.819607843137255 0.933333333333333 1" />
      </material>
    </visual>
    <collision>
      <origin
        xyz="0 0 0"
        rpy="0 0 0" />
      <geometry>
        <mesh
          filename="package://AAAckermann_for sim/meshes/back_right.STL" />
      </geometry>
    </collision>
  </link>
  <joint
    name="back_right_joint"
    type="continuous">
    <origin
      xyz="0.0652241619934794 0.0315 0"
      rpy="3.14159265358979 1.19455810050953 1.5707963267949" />
    <parent
      link="streeing_right" />
    <child
      link="back_right" />
    <axis
      xyz="0 1 0" />
  </joint>
</robot>