<?xml version="1.0" encoding="utf-8"?>
<!-- This URDF was automatically created by SolidWorks to URDF Exporter! Originally created by Stephen Brawner (brawner@gmail.com) 
     Commit Version: 1.6.0-4-g7f85cfe  Build Version: 1.6.7995.38578
     For more information, please see http://wiki.ros.org/sw_urdf_exporter -->
<robot
  name="AAAckermann">
  <link
    name="base_link">
    <inertial>
      <origin
        xyz="-0.0651994405179663 4.22434509872449E-07 -0.0239634712761258"
        rpy="0 0 0" />
      <mass
        value="5.25555128497609" />
      <inertia
        ixx="0.0414328478617682"
        ixy="-1.82796488685318E-07"
        ixz="3.45960820664179E-07"
        iyy="0.0417152661425413"
        iyz="1.05010040923958E-07"
        izz="0.0821338918053197" />
    </inertial>
    <visual>
      <origin
        xyz="0 0 0"
        rpy="0 0 0" />
      <geometry>
        <mesh
          filename="package://AAAckermann/meshes/base_link.STL" />
      </geometry>
      <material
        name="">
        <color
          rgba="1 1 1 0.4" />
      </material>
    </visual>
    <collision>
      <origin
        xyz="0 0 0"
        rpy="0 0 0" />
      <geometry>
        <mesh
          filename="package://AAAckermann/meshes/base_link.STL" />
      </geometry>
    </collision>
  </link>
  <link
    name="front_left">
    <inertial>
      <origin
        xyz="3.8858E-15 -0.015274 4.6435E-14"
        rpy="0 0 0" />
      <mass
        value="0.24047" />
      <inertia
        ixx="0.00024514"
        ixy="5.4339E-21"
        ixz="-6.7763E-21"
        iyy="0.00045262"
        iyz="6.4709E-20"
        izz="0.00024514" />
    </inertial>
    <visual>
      <origin
        xyz="0 0 0"
        rpy="0 0 0" />
      <geometry>
        <mesh
          filename="package://AAAckermann/meshes/front_left.STL" />
      </geometry>
      <material
        name="">
        <color
          rgba="0 1 0 0.5" />
      </material>
    </visual>
    <collision>
      <origin
        xyz="0 0 0"
        rpy="0 0 0" />
      <geometry>
        <mesh
          filename="package://AAAckermann/meshes/front_left.STL" />
      </geometry>
    </collision>
  </link>
  <joint
    name="front_left_joint"
    type="continuous">
    <origin
      xyz="0.0190000000000679 0.301000000000045 -0.0695000000000887"
      rpy="3.14159265358979 0.0849179307157281 3.14159265358979" />
    <parent
      link="base_link" />
    <child
      link="front_left" />
    <axis
      xyz="0 1 0" />
  </joint>
  <link
    name="front_right">
    <inertial>
      <origin
        xyz="-2.9643E-14 0.025726 3.5749E-14"
        rpy="0 0 0" />
      <mass
        value="0.24047" />
      <inertia
        ixx="0.00024514"
        ixy="5.2554E-21"
        ixz="0"
        iyy="0.00045262"
        iyz="4.3994E-20"
        izz="0.00024514" />
    </inertial>
    <visual>
      <origin
        xyz="0 0 0"
        rpy="0 0 0" />
      <geometry>
        <mesh
          filename="package://AAAckermann/meshes/front_right.STL" />
      </geometry>
      <material
        name="">
        <color
          rgba="0 1 0 0.5" />
      </material>
    </visual>
    <collision>
      <origin
        xyz="0 0 0"
        rpy="0 0 0" />
      <geometry>
        <mesh
          filename="package://AAAckermann/meshes/front_right.STL" />
      </geometry>
    </collision>
  </link>
  <joint
    name="front_right_joint"
    type="continuous">
    <origin
      xyz="0.0190000000000679 -0.259999999999977 -0.0695000000000887"
      rpy="3.14159265358979 -0.692237011731428 0" />
    <parent
      link="base_link" />
    <child
      link="front_right" />
    <axis
      xyz="0 1 0" />
  </joint>
  <link
    name="left_steering">
    <inertial>
      <origin
        xyz="0.0121532099874294 -0.0166916241895938 -0.0211847288398316"
        rpy="0 0 0" />
      <mass
        value="0.0405602056975407" />
      <inertia
        ixx="1.43958495481578E-05"
        ixy="-1.73339990683825E-06"
        ixz="-7.11935154287877E-06"
        iyy="2.95171085845272E-05"
        iyz="2.08772590818048E-06"
        izz="3.10994722329793E-05" />
    </inertial>
    <visual>
      <origin
        xyz="0 0 0"
        rpy="0 0 0" />
      <geometry>
        <mesh
          filename="package://AAAckermann/meshes/left_steering.STL" />
      </geometry>
      <material
        name="">
        <color
          rgba="0.792156862745098 0.819607843137255 0.933333333333333 1" />
      </material>
    </visual>
    <collision>
      <origin
        xyz="0 0 0"
        rpy="0 0 0" />
      <geometry>
        <mesh
          filename="package://AAAckermann/meshes/left_steering.STL" />
      </geometry>
    </collision>
  </link>
  <joint
    name="left_steering_joint"
    type="continuous">
    <origin
      xyz="-0.544750000000063 0.229999999999977 -0.0837500000002837"
      rpy="3.14159265358979 0 -0.00209254658538632" />
    <parent
      link="base_link" />
    <child
      link="left_steering" />
    <axis
      xyz="0 0 1" />
  </joint>
  <link
    name="rear_left">
    <inertial>
      <origin
        xyz="-1.5192E-06 0.025619 0.006692"
        rpy="0 0 0" />
      <mass
        value="0.24047" />
      <inertia
        ixx="0.00024514"
        ixy="-4.9967E-09"
        ixz="-5.3615E-10"
        iyy="0.00045026"
        iyz="2.201E-05"
        izz="0.0002475" />
    </inertial>
    <visual>
      <origin
        xyz="0 0 0"
        rpy="0 0 0" />
      <geometry>
        <mesh
          filename="package://AAAckermann/meshes/rear_left.STL" />
      </geometry>
      <material
        name="">
        <color
          rgba="0 1 0 0.5" />
      </material>
    </visual>
    <collision>
      <origin
        xyz="0 0 0"
        rpy="0 0 0" />
      <geometry>
        <mesh
          filename="package://AAAckermann/meshes/rear_left.STL" />
      </geometry>
    </collision>
  </link>
  <joint
    name="rear_left_joint"
    type="continuous">
    <origin
      xyz="0 -0.0367488381424265 -0.0159999999999999"
      rpy="3.14159265358979 1.57056930363849 0" />
    <parent
      link="left_steering" />
    <child
      link="rear_left" />
    <axis
      xyz="0 1 0" />
  </joint>
  <link
    name="right_steering">
    <inertial>
      <origin
        xyz="-0.0138648104691156 -0.0152975676601856 -0.021184728839829"
        rpy="0 0 0" />
      <mass
        value="0.0405602056975408" />
      <inertia
        ixx="1.49389187707206E-05"
        ixy="3.30295116006257E-06"
        ixz="7.3015684371967E-06"
        iyy="2.89780797923847E-05"
        iyz="1.31491150207248E-06"
        izz="3.11035126633983E-05" />
    </inertial>
    <visual>
      <origin
        xyz="0 0 0"
        rpy="0 0 0" />
      <geometry>
        <mesh
          filename="package://AAAckermann/meshes/right_steering.STL" />
      </geometry>
      <material
        name="">
        <color
          rgba="0.792156862745098 0.819607843137255 0.933333333333333 1" />
      </material>
    </visual>
    <collision>
      <origin
        xyz="0 0 0"
        rpy="0 0 0" />
      <geometry>
        <mesh
          filename="package://AAAckermann/meshes/right_steering.STL" />
      </geometry>
    </collision>
  </link>
  <joint
    name="right_steering_joint"
    type="continuous">
    <origin
      xyz="-0.544750000000063 -0.230000000000023 -0.0837500000002836"
      rpy="3.14159265358979 0 -3.13242627228221" />
    <parent
      link="base_link" />
    <child
      link="right_steering" />
    <axis
      xyz="0 0 1" />
  </joint>
  <link
    name="rear_right">
    <inertial>
      <origin
        xyz="1.415E-10 0.025722 1.2793E-08"
        rpy="0 0 0" />
      <mass
        value="0.24047" />
      <inertia
        ixx="0.00024514"
        ixy="4.6696E-13"
        ixz="9.4021E-20"
        iyy="0.00045262"
        iyz="4.2319E-11"
        izz="0.00024514" />
    </inertial>
    <visual>
      <origin
        xyz="0 0 0"
        rpy="0 0 0" />
      <geometry>
        <mesh
          filename="package://AAAckermann/meshes/rear_right.STL" />
      </geometry>
      <material
        name="">
        <color
          rgba="0 1 0 0.5" />
      </material>
    </visual>
    <collision>
      <origin
        xyz="0 0 0"
        rpy="0 0 0" />
      <geometry>
        <mesh
          filename="package://AAAckermann/meshes/rear_right.STL" />
      </geometry>
    </collision>
  </link>
  <joint
    name="rear_right_joint"
    type="continuous">
    <origin
      xyz="0 -0.0370034448281129 -0.0159999999999995"
      rpy="3.14159265358979 -1.55976234848309 0" />
    <parent
      link="right_steering" />
    <child
      link="rear_right" />
    <axis
      xyz="0 1 0" />
  </joint>
</robot>