<?xml version="1.0" encoding="utf-8"?>
<!-- This URDF was automatically created by SolidWorks to URDF Exporter! Originally created by Stephen Brawner (brawner@gmail.com) 
     Commit Version: 1.6.0-4-g7f85cfe  Build Version: 1.6.7995.38578
     For more information, please see http://wiki.ros.org/sw_urdf_exporter -->
<robot
  name="holonomic_update_flok">
  <link
    name="base_link">
    <inertial>
      <origin
        xyz="4.10852596388622E-09 0.138132047801609 -0.0286373816091294"
        rpy="0 0 0" />
      <mass
        value="4.06765972668113" />
      <inertia
        ixx="0.070880196028319"
        ixy="-1.00494774701654E-18"
        ixz="-6.12703676459084E-14"
        iyy="0.0147342890344283"
        iyz="-2.84366609830377E-08"
        izz="0.0852478897588496" />
    </inertial>
    <visual>
      <origin
        xyz="0 0 0"
        rpy="0 0 0" />
      <geometry>
        <mesh
          filename="package://holonomic_update_flok/meshes/base_link.STL" />
      </geometry>
      <material
        name="">
        <color
          rgba="0.898039215686275 0.917647058823529 0.929411764705882 1" />
      </material>
    </visual>
    <collision>
      <origin
        xyz="0 0 0"
        rpy="0 0 0" />
      <geometry>
        <mesh
          filename="package://holonomic_update_flok/meshes/base_link.STL" />
      </geometry>
    </collision>
  </link>
  <link
    name="wheel_fr_right">
    <inertial>
      <origin
        xyz="-2.7756E-17 2.7756E-16 -0.026447"
        rpy="0 0 0" />
      <mass
        value="0.32138" />
      <inertia
        ixx="9.1337E-05"
        ixy="-1.6659E-18"
        ixz="2.6903E-19"
        iyy="9.1337E-05"
        iyz="7.8331E-17"
        izz="0.00011244" />
    </inertial>
    <visual>
      <origin
        xyz="0 0 0"
        rpy="0 0 0" />
      <geometry>
        <mesh
          filename="package://holonomic_update_flok/meshes/wheel_fr_right.STL" />
      </geometry>
      <material
        name="">
        <color
          rgba="0.77647 0.75686 0.73725 1" />
      </material>
    </visual>
    <collision>
      <origin
        xyz="0 0 0"
        rpy="0 0 0" />
      <geometry>
        <mesh
          filename="package://holonomic_update_flok/meshes/wheel_fr_right.STL" />
      </geometry>
    </collision>
  </link>
  <joint
    name="joint_fr_right"
    type="continuous">
    <origin
      xyz="0.195390712673453 0.172500000000105 -0.0499999999993335"
      rpy="1.5707963267949 0 1.5707963267949" />
    <parent
      link="base_link" />
    <child
      link="wheel_fr_right" />
    <axis
      xyz="0 0 -1" />
  </joint>
  <link
    name="wheel_bk_right">
    <inertial>
      <origin
        xyz="5.55111512312578E-17 -6.10622663543836E-16 -0.0264473304136225"
        rpy="0 0 0" />
      <mass
        value="0.321375664058358" />
      <inertia
        ixx="9.13370307716787E-05"
        ixy="-1.37428919496607E-19"
        ixz="1.08252219380439E-19"
        iyy="9.13370307716799E-05"
        iyz="-7.64908464428148E-17"
        izz="0.000112444996454045" />
    </inertial>
    <visual>
      <origin
        xyz="0 0 0"
        rpy="0 0 0" />
      <geometry>
        <mesh
          filename="package://holonomic_update_flok/meshes/wheel_bk_right.STL" />
      </geometry>
      <material
        name="">
        <color
          rgba="0.776470588235294 0.756862745098039 0.737254901960784 1" />
      </material>
    </visual>
    <collision>
      <origin
        xyz="0 0 0"
        rpy="0 0 0" />
      <geometry>
        <mesh
          filename="package://holonomic_update_flok/meshes/wheel_bk_right.STL" />
      </geometry>
    </collision>
  </link>
  <joint
    name="joint_bk_right"
    type="continuous">
    <origin
      xyz="0.195390712673453 -0.192499999999916 -0.0499999999992868"
      rpy="-1.5707963267949 0 -1.5707963267949" />
    <parent
      link="base_link" />
    <child
      link="wheel_bk_right" />
    <axis
      xyz="0 0 -1" />
  </joint>
  <link
    name="wheel_fr_left">
    <inertial>
      <origin
        xyz="-2.4980018054066E-16 -4.9960036108132E-16 -0.0264433822598773"
        rpy="0 0 0" />
      <mass
        value="0.321375664058358" />
      <inertia
        ixx="9.13370307716877E-05"
        ixy="-3.60087655180789E-19"
        ixz="1.28262856809876E-19"
        iyy="9.1337030771692E-05"
        iyz="-7.42631833022157E-17"
        izz="0.000112444996454058" />
    </inertial>
    <visual>
      <origin
        xyz="0 0 0"
        rpy="0 0 0" />
      <geometry>
        <mesh
          filename="package://holonomic_update_flok/meshes/wheel_fr_left.STL" />
      </geometry>
      <material
        name="">
        <color
          rgba="0.776470588235294 0.756862745098039 0.737254901960784 1" />
      </material>
    </visual>
    <collision>
      <origin
        xyz="0 0 0"
        rpy="0 0 0" />
      <geometry>
        <mesh
          filename="package://holonomic_update_flok/meshes/wheel_fr_left.STL" />
      </geometry>
    </collision>
  </link>
  <joint
    name="joint_fr_left"
    type="continuous">
    <origin
      xyz="-0.1953907126735 0.172500000000105 -0.049999999999286"
      rpy="1.5707963267949 0 -1.5707963267949" />
    <parent
      link="base_link" />
    <child
      link="wheel_fr_left" />
    <axis
      xyz="0 0 1" />
  </joint>
  <link
    name="wheel_bk_left">
    <inertial>
      <origin
        xyz="3.33066907387547E-16 -1.11022302462516E-16 -0.0264433822598772"
        rpy="0 0 0" />
      <mass
        value="0.321375664058358" />
      <inertia
        ixx="9.13370307716783E-05"
        ixy="-3.06049241482693E-20"
        ixz="4.54787112568744E-19"
        iyy="9.13370307716817E-05"
        iyz="-7.42221339408628E-17"
        izz="0.000112444996454046" />
    </inertial>
    <visual>
      <origin
        xyz="0 0 0"
        rpy="0 0 0" />
      <geometry>
        <mesh
          filename="package://holonomic_update_flok/meshes/wheel_bk_left.STL" />
      </geometry>
      <material
        name="">
        <color
          rgba="0.776470588235294 0.756862745098039 0.737254901960784 1" />
      </material>
    </visual>
    <collision>
      <origin
        xyz="0 0 0"
        rpy="0 0 0" />
      <geometry>
        <mesh
          filename="package://holonomic_update_flok/meshes/wheel_bk_left.STL" />
      </geometry>
    </collision>
  </link>
  <joint
    name="joint_bk_left"
    type="continuous">
    <origin
      xyz="-0.1953907126735 -0.192499999999917 -0.049999999999286"
      rpy="1.5707963267949 0 -1.5707963267949" />
    <parent
      link="base_link" />
    <child
      link="wheel_bk_left" />
    <axis
      xyz="0 0 1" />
  </joint>
</robot>