<?xml version="1.0"?>
<robot xmlns:xacro="http://www.ros.org/wiki/xacro" name="ackermann" >
  <link name="base_footprint_ack">
  </link>
  <joint name="base_link_ack_to_base_footprint_ack" type="fixed">
    <origin xyz="0 0 0.12" rpy="0 0 1.57"/>
    <parent link="base_footprint_ack"/>
    <child link="base_link_ack"/>
  </joint>

  <link
    name="base_link_ack">
    <inertial>
      <origin
        xyz="-4.21303280262464E-07 -0.0595327816236317 -0.0394837308817142"
        rpy="0 0 0" />
      <mass
        value="1" />
      <inertia
        ixx="0.01" ixy="0.0" ixz="0.0"
        iyy="0.01" iyz="0.0"
        izz="0.01"/>
    </inertial>
    <visual>
      <origin
        xyz="0 0 0"
        rpy="0 0 0" />
      <geometry>
        <mesh
          filename="file:///$(find my_robot_description)/meshes/ackermann_meshes/base_link.STL" />
      </geometry>
      <material
        name="">
        <color
          rgba="1 1 1 0.4" />
      </material>
    </visual>
    <collision>
      <origin
        xyz="0 0 0"
        rpy="0 0 0" />
      <geometry>
        <mesh
          filename="file:///$(find my_robot_description)/meshes/ackermann_meshes/base_link.STL" />
      </geometry>
    </collision>
  </link>
  <link
    name="front_left">
    <inertial>
      <origin
        xyz="9.4647E-14 -0.015274 3.8664E-14"
        rpy="0 0 0" />
      <mass
        value="0.2" />
      <inertia
        ixx="0.01" ixy="0.0" ixz="0.0"
        iyy="0.01" iyz="0.0"
        izz="0.01"/>
    </inertial>
    <visual>
      <origin
        xyz="0 0 0"
        rpy="0 0 0" />
      <geometry>
        <mesh
          filename="file:///$(find my_robot_description)/meshes/ackermann_meshes/front_left.STL" />
      </geometry>
      <material
        name="">
        <color
          rgba="0 1 0 0.5" />
      </material>
    </visual>
    <collision>
      <origin
        xyz="0 0 0"
        rpy="0 0 0" />
      <geometry>
        <mesh
          filename="file:///$(find my_robot_description)/meshes/ackermann_meshes/front_left.STL" />
      </geometry>
    </collision>
  </link>
  <joint
    name="front_left_joint"
    type="continuous">
    <origin
      xyz="-0.301000000000045 0.0190000000000679 -0.0695000000000887"
      rpy="3.14159265358979 0.0849179307157281 -1.5707963267949" />
    <parent
      link="base_link_ack" />
    <child
      link="front_left" />
    <axis
      xyz="0 -1 0" />
  </joint>
  <link
    name="front_right">
    <inertial>
      <origin
        xyz="-9.9698E-14 0.025726 -2.2427E-14"
        rpy="0 0 0" />
      <mass
        value="0.2" />
      <inertia
        ixx="0.01" ixy="0.0" ixz="0.0"
        iyy="0.01" iyz="0.0"
        izz="0.01"/>
    </inertial>
    <visual>
      <origin
        xyz="0 0 0"
        rpy="0 0 0" />
      <geometry>
        <mesh
          filename="file:///$(find my_robot_description)/meshes/ackermann_meshes/front_right.STL" />
      </geometry>
      <material
        name="">
        <color
          rgba="0 1 0 0.5" />
      </material>
    </visual>
    <collision>
      <origin
        xyz="0 0 0"
        rpy="0 0 0" />
      <geometry>
        <mesh
          filename="file:///$(find my_robot_description)/meshes/ackermann_meshes/front_right.STL" />
      </geometry>
    </collision>
  </link>
  <joint
    name="front_right_joint"
    type="continuous">
    <origin
      xyz="0.259999999999977 0.0190000000000679 -0.0695000000000887"
      rpy="3.14159265358979 -0.692237011731428 1.5707963267949" />
    <parent
      link="base_link_ack" />
    <child
      link="front_right" />
    <axis
      xyz="0 1 0" />
  </joint>
  <link
    name="left_steering">
    <inertial>
      <origin
        xyz="0.013865 -0.0153 -0.021185"
        rpy="0 0 0" />
      <mass
        value="0.2" />
      <inertia
        ixx="0.01" ixy="0.0" ixz="0.0"
        iyy="0.01" iyz="0.0"
        izz="0.01"/>
    </inertial>
    <visual>
      <origin
        xyz="0 0 0"
        rpy="0 0 0" />
      <geometry>
        <mesh
          filename="file:///$(find my_robot_description)/meshes/ackermann_meshes/left_steering.STL" />
      </geometry>
      <material
        name="">
        <color
          rgba="0.79216 0.81961 0.93333 1" />
      </material>
    </visual>
    <collision>
      <origin
        xyz="0 0 0"
        rpy="0 0 0" />
      <geometry>
        <mesh
          filename="file:///$(find my_robot_description)/meshes/ackermann_meshes/left_steering.STL" />
      </geometry>
    </collision>
  </link>
  <joint
    name="left_steering_joint"
    type="continuous">
    <origin
      xyz="-0.229999999999977 -0.544750000000063 -0.0837500000002837"
      rpy="3.14159265358979 0 1.56870378020951" />
    <parent
      link="base_link_ack" />
    <child
      link="left_steering" />
    <axis
      xyz="0 0 1" />
  </joint>
  <link
    name="rear_left">
    <inertial>
      <origin
        xyz="-3.3074E-13 0.025977 4.563E-14"
        rpy="0 0 0" />
      <mass
        value="0.2" />
      <inertia
        ixx="0.01" ixy="0.0" ixz="0.0"
        iyy="0.01" iyz="0.0"
        izz="0.01"/>
    </inertial>
    <visual>
      <origin
        xyz="0 0 0"
        rpy="0 0 0" />
      <geometry>
        <mesh
          filename="file:///$(find my_robot_description)/meshes/ackermann_meshes/rear_left.STL" />
      </geometry>
      <material
        name="">
        <color
          rgba="0 1 0 0.5" />
      </material>
    </visual>
    <collision>
      <origin
        xyz="0 0 0"
        rpy="0 0 0" />
      <geometry>
        <mesh
          filename="file:///$(find my_robot_description)/meshes/ackermann_meshes/rear_left.STL" />
      </geometry>
    </collision>
  </link>
  <joint
    name="rear_left_joint"
    type="continuous">
    <origin
      xyz="0 -0.0367488381424265 -0.0159999999999999"
      rpy="3.14159265358979 1.57056930363849 0" />
    <parent
      link="left_steering" />
    <child
      link="rear_left" />
    <axis
      xyz="0 1 0" />
  </joint>
  <link
    name="right_steering">
    <inertial>
      <origin
        xyz="-0.0138648135893726 -0.0152975648321685 -0.0211847288398291"
        rpy="0 0 0" />
      <mass
        value="0.202056975407" />
      <inertia
        ixx="0.01" ixy="0.0" ixz="0.0"
        iyy="0.01" iyz="0.0"
        izz="0.01"/>
    </inertial>
    <visual>
      <origin
        xyz="0 0 0"
        rpy="0 0 0" />
      <geometry>
        <mesh
          filename="file:///$(find my_robot_description)/meshes/ackermann_meshes/right_steering.STL" />
      </geometry>
      <material
        name="">
        <color
          rgba="0.792156862745098 0.819607843137255 0.933333333333333 1" />
      </material>
    </visual>
    <collision>
      <origin
        xyz="0 0 0"
        rpy="0 0 0" />
      <geometry>
        <mesh
          filename="file:///$(find my_robot_description)/meshes/ackermann_meshes/right_steering.STL" />
      </geometry>
    </collision>
  </link>
  <joint
    name="right_steering_joint"
    type="continuous">
    <origin
      xyz="0.230000000000023 -0.544750000000063 -0.0837500000002836"
      rpy="3.14159265358979 0 -1.56162994548732" />
    <parent
      link="base_link_ack" />
    <child
      link="right_steering" />
    <axis
      xyz="0 0 1" />
  </joint>
  <link
    name="rear_right">
    <inertial>
      <origin
        xyz="3.3534E-13 0.025722 -9.3148E-14"
        rpy="0 0 0" />
      <mass
        value="0.2" />
      <inertia
        ixx="0.01" ixy="0.0" ixz="0.0"
        iyy="0.01" iyz="0.0"
        izz="0.01"/>
    </inertial>
    <visual>
      <origin
        xyz="0 0 0"
        rpy="0 0 0" />
      <geometry>
        <mesh
          filename="file:///$(find my_robot_description)/meshes/ackermann_meshes/rear_right.STL" />
      </geometry>
      <material
        name="">
        <color
          rgba="0 1 0 0.5" />
      </material>
    </visual>
    <collision>
      <origin
        xyz="0 0 0"
        rpy="0 0 0" />
      <geometry>
        <mesh
          filename="file:///$(find my_robot_description)/meshes/ackermann_meshes/rear_right.STL" />
      </geometry>
    </collision>
  </link>
  <joint
    name="rear_right_joint"
    type="continuous">
    <origin
      xyz="0 -0.0370034448281129 -0.0159999999999995"
      rpy="3.14159265358979 -1.55976234848309 0" />
    <parent
      link="right_steering" />
    <child
      link="rear_right" />
    <axis
      xyz="0 1 0" />
  </joint>

 <gazebo>
    <plugin name="gazebo_ros_ackermann_drive" filename="libgazebo_ros_ackermann_drive.so">
      <ros>
        <namespace>/ackermann</namespace>
      </ros>

      <update_rate>100.0</update_rate>


      <wheel_base>0.65</wheel_base>
      <wheel_separation>0.55</wheel_separation>
      <wheel_radius>0.06</wheel_radius>

      <!-- wheels -->
      <front_left_joint>rear_right_joint</front_left_joint>
      <front_right_joint>rear_left_joint</front_right_joint>
      <rear_left_joint>front_right_joint</rear_left_joint>
      <rear_right_joint>front_left_joint</rear_right_joint>

      <!-- <front_left_joint>front_left_joint</front_left_joint>
      <front_right_joint>front_right_joint</front_right_joint>
      <rear_left_joint>rear_left_joint</rear_left_joint>
      <rear_right_joint>rear_right_joint</rear_right_joint> -->

      <!-- steering joints -->
      <left_steering_joint>left_steering_joint</left_steering_joint>
      <right_steering_joint>right_steering_joint</right_steering_joint>

      <!-- Max absolute steer angle for tyre in radians-->
      <!-- Any cmd_vel angular z greater than this would be capped -->
      <max_steer>0.6458</max_steer>

      <!-- Max absolute steering angle of steering wheel -->
      <max_steering_angle>7.85</max_steering_angle>

      <!-- Max absolute linear speed in m/s -->
      <max_speed>20</max_speed>

      <!-- PID tuning -->
      <left_steering_pid_gain>1 0 1</left_steering_pid_gain>
      <left_steering_i_range>0 0</left_steering_i_range>
      <right_steering_pid_gain>1 0 1</right_steering_pid_gain>
      <right_steering_i_range>0 0</right_steering_i_range>
      <linear_velocity_pid_gain>1000 0 1</linear_velocity_pid_gain>
      <linear_velocity_i_range>0 0</linear_velocity_i_range>

      <!-- output -->
      <publish_odom>true</publish_odom>
      <publish_odom_tf>true</publish_odom_tf>
      <publish_wheel_tf>true</publish_wheel_tf>
      <publish_distance>true</publish_distance>

      <odometry_frame>odom_ack</odometry_frame>
      <robot_base_frame>base_footprint_ack</robot_base_frame>
    </plugin>
  </gazebo>
</robot>