<?xml version="1.0"?>
<robot xmlns:xacro="http://www.ros.org/wiki/xacro" name="diffdrive" >
<!-- This URDF was automatically created by SolidWorks to URDF Exporter! Originally created by Stephen Brawner (brawner@gmail.com) 
     Commit Version: 1.6.0-4-g7f85cfe  Build Version: 1.6.7995.38578
     For more information, please see http://wiki.ros.org/sw_urdf_exporter -->
  
  <material name="wheel">
    <color rgba="0 1 0 0.5" /> </material>
    
  <link name="base_footprint_diff"></link>
  <joint name="base_link_diff_to_base_footprint_diff" type="fixed">
    <origin xyz="0 0 0" rpy="0 0 3.14159265"/>
    <parent link="base_footprint_diff"/>
    <child link="base_link_diff"/>
  </joint>

  <link name="laser_frame_diff">
    <visual>
      <geometry>
        <cylinder radius="0.05" length="0.04"/>
      </geometry>
    </visual>
    <collision>
      <geometry>
        <cylinder radius="0.05" length="0.04"/>
      </geometry>
    </collision>
      <inertial>
      <origin
        xyz="0 0 0"
        rpy="0 0 0" />
      <mass
        value="0.1" />
      <inertia
        ixx="0.01" ixy="0.0" ixz="0.0"
        iyy="0.01" iyz="0.0"
        izz="0.01"/>
    </inertial>
  </link>

  <joint name="laser_joint" type="fixed">
    <origin xyz="0 0 0.12" rpy="0 0 0"/>
    <parent link="base_link_diff"/>
    <child link="laser_frame_diff"/>
  </joint>

  <link
    name="base_link_diff">
    <inertial>
      <origin
        xyz="-0.00843797932248264 7.91524717263514E-05 0.0510944704707574"
        rpy="0 0 0" />
      <mass
        value="5.20115624935193" />
      <inertia
        ixx="0.0441950216113175"
        ixy="-6.1273841754346E-08"
        ixz="1.5363609769836E-06"
        iyy="0.0338853571996096"
        iyz="2.75308042467669E-07"
        izz="0.077237000418039" />
    </inertial>
    <visual>
      <origin
        xyz="0 0 0"
        rpy="0 0 0" />
      <geometry>
        <mesh
          filename="file:///$(find my_robot_description)/meshes/diffdrive_meshes/base_link.STL" />
      </geometry>
      <material
        name="">
        <color
          rgba="0.752941176470588 0.752941176470588 0.752941176470588 1" />
      </material>
    </visual>
    <collision>
      <origin
        xyz="0 0 0"
        rpy="0 0 0" />
      <geometry>
        <mesh
          filename="file:///$(find my_robot_description)/meshes/diffdrive_meshes/base_link.STL" />
      </geometry>
    </collision>
  </link>
  <link
    name="wheel_left">
    <inertial>
      <origin
        xyz="0 0.0257257525083612 -2.77555756156289E-17"
        rpy="0 0 0" />
      <mass
        value="2.40470068076377" />
      <inertia
        ixx="0.000245137261047142"
        ixy="5.12745004835681E-20"
        ixz="0"
        iyy="0.000452624182450971"
        iyz="-5.57841424911612E-20"
        izz="0.000245137261047142" />
    </inertial>
    <visual>
      <origin
        xyz="0 0 0"
        rpy="0 0 0" />
      <geometry>
        <mesh
          filename="file:///$(find my_robot_description)/meshes/diffdrive_meshes/wheel_left.STL" />
      </geometry>
      <material name="wheel" /> 
    </visual>
    <collision>
      <origin
        xyz="0 0 0"
        rpy="0 0 0" />
      <geometry>
        <mesh
          filename="file:///$(find my_robot_description)/meshes/diffdrive_meshes/wheel_left.STL" />
      </geometry>
    </collision>
  </link>
  <joint
    name="left_wheel_joint"
    type="continuous">
    <origin
      xyz="-0.000999999999839296 -0.249999999999933 0.0305000000006919"
      rpy="0 0.774914173734372 3.14159265358979" />
    <parent
      link="base_link_diff" />
    <child
      link="wheel_left" />
    <axis
      xyz="0 1 0" />
  </joint>
  <link
    name="wheel_right">
    <inertial>
      <origin
        xyz="5.55111512312578E-17 0.0257257525083612 5.55111512312578E-17"
        rpy="0 0 0" />
      <mass
        value="2.40470068076377" />
      <inertia
        ixx="0.000245137261047143"
        ixy="4.26861241081053E-21"
        ixz="-6.7762635780344E-21"
        iyy="0.000452624182450972"
        iyz="1.59972478988236E-20"
        izz="0.000245137261047143" />
    </inertial>
    <visual>
      <origin
        xyz="0 0 0"
        rpy="0 0 0" />
      <geometry>      
        <mesh
          filename="file:///$(find my_robot_description)/meshes/diffdrive_meshes/wheel_right.STL" />
      </geometry>
      <material name="wheel" />     
    </visual>
    <collision>
      <origin
        xyz="0 0 0"
        rpy="0 0 0" />
      <geometry>
        <mesh
          filename="file:///$(find my_robot_description)/meshes/diffdrive_meshes/wheel_right.STL" />
      </geometry>
    </collision>
  </link>
  <joint
    name="right_wheel_joint"
    type="continuous">
    <origin
      xyz="-0.000999999999862333 0.250000000000088 0.0305000000006919"
      rpy="3.14159265358979 -0.53712555837446 3.14159265358979" />
    <parent
      link="base_link_diff" />
    <child
      link="wheel_right" />
    <axis
      xyz="0 -1 0" />
  </joint>


  <gazebo>
      <plugin filename="libgazebo_ros2_control.so" name="gazebo_ros2_control">
        <namespace>diffdrive</namespace>
        <robot_param>robot_description</robot_param>
        <robot_param_node>robot_state_publisher</robot_param_node>
        <parameters>$(find coop_robot_bringup)/config/diff_controller.yaml</parameters>
        <controller_manager_name>controller_manager</controller_manager_name>
      </plugin>
  </gazebo>

  <ros2_control name="GazeboSystem" type="system">
    <hardware>
      <plugin>gazebo_ros2_control/GazeboSystem</plugin>
    </hardware>
    <joint name="left_wheel_joint">
      <command_interface name="velocity">
        <param name="min">-0.5</param>
        <param name="max">0.5</param>
      </command_interface>
      <state_interface name="position"/>
      <state_interface name="velocity"/>
    </joint>
    <joint name="right_wheel_joint">
      <command_interface name="velocity">
        <param name="min">-0.5</param>
        <param name="max">0.5</param>
      </command_interface>
      <state_interface name="position"/>
      <state_interface name="velocity"/>
    </joint>
  </ros2_control>


    <gazebo reference="wheel_right">
      <material>Gazebo/Green</material>
    </gazebo>

    <gazebo reference="wheel_left">
      <material>Gazebo/Green</material>
    </gazebo>
    
    <gazebo reference="base_link_diff">
      <material>Gazebo/White</material>
    </gazebo>


    <gazebo reference="laser_frame_diff">
        <material>Gazebo/Black</material>

        <sensor name="laser" type="ray">
            <pose> 0 0 0 0 0 0 </pose>
            <visualize>false</visualize>
            <update_rate>10</update_rate>
            <ray>
                <scan>
                    <horizontal>
                        <samples>360</samples>
                        <min_angle>-3.14</min_angle>
                        <max_angle>3.14</max_angle>
                    </horizontal>
                </scan>
                <range>
                    <min>0.3</min>
                    <max>12</max>
                </range>
            </ray>
            <plugin name="laser_controller_diff" filename="libgazebo_ros_ray_sensor.so">
                <ros>
                    <argument>~/out:=scan_diff</argument>
                </ros>
                <output_type>sensor_msgs/LaserScan</output_type>
                <frame_name>laser_frame_diff</frame_name>
            </plugin>
        </sensor>
    </gazebo>


</robot>