<?xml version="1.0"?>
<robot xmlns:xacro="http://www.ros.org/wiki/xacro" name="diffdrive" >
<!-- This URDF was automatically created by SolidWorks to URDF Exporter! Originally created by Stephen Brawner (brawner@gmail.com) 
     Commit Version: 1.6.0-4-g7f85cfe  Build Version: 1.6.7995.38578
     For more information, please see http://wiki.ros.org/sw_urdf_exporter -->
  
  <material name="wheel">
    <color rgba="0 1 0 0.5" /> </material>
    
  <link name="base_footprint_diff"></link>
  <joint name="base_link_diff_to_base_footprint_diff" type="fixed">
    <origin xyz="0 0 0" rpy="0 0 3.14159265"/>
    <parent link="base_footprint_diff"/>
    <child link="base_link_diff"/>
  </joint>

  <link name="laser_frame_diff">
    <visual>
      <geometry>
        <cylinder radius="0.05" length="0.04"/>
      </geometry>
    </visual>
    <collision>
      <geometry>
        <cylinder radius="0.05" length="0.04"/>
      </geometry>
    </collision>
      <inertial>
      <origin
        xyz="0 0 0"
        rpy="0 0 0" />
      <mass
        value="0.1" />
      <inertia
        ixx="0.01" ixy="0.0" ixz="0.0"
        iyy="0.01" iyz="0.0"
        izz="0.01"/>
    </inertial>
  </link>

  <joint name="laser_joint" type="fixed">
    <origin xyz="0 0 0.12" rpy="0 0 0"/>
    <parent link="base_link_diff"/>
    <child link="laser_frame_diff"/>
  </joint>

  <link
    name="base_link_diff">
    <inertial>
      <origin
        xyz="-0.0244064139228468 -6.45065062421235E-07 0.0569804687199345"
        rpy="0 0 0" />
      <mass
        value="1.66720366185749" />
      <inertia
        ixx="0.01" ixy="0.0" ixz="0.0"
        iyy="0.01" iyz="0.0"
        izz="0.01"/>
    </inertial>
    <visual>
      <origin
        xyz="0 0 0"
        rpy="0 0 0" />
      <geometry>
        <mesh
          filename="file:///$(find my_robot_description)/meshes/diffdrive_meshes/base_link.STL" />
      </geometry>
      <material
        name="">
        <color
          rgba="0.752941176470588 0.752941176470588 0.752941176470588 1" />
      </material>
    </visual>
    <collision>
      <origin
        xyz="0 0 0"
        rpy="0 0 0" />
      <geometry>
        <mesh
          filename="file:///$(find my_robot_description)/meshes/diffdrive_meshes/base_link.STL" />
      </geometry>
     <surface>
        <poissons_ratio>0.347</poissons_ratio>
        <elastic_modulus>8.8e+09</elastic_modulus>
        <ode>
          <soft_cfm>2e+20</soft_cfm>
          <soft_erp>2e+40</soft_erp>
          <kp>1000</kp>
          <kd>1</kd>
          <max_vel>0.01</max_vel>
          <min_depth>1.0</min_depth>
        </ode>
      </surface>
    </collision>
  </link>
  <link
    name="Wheel_left">
    <inertial>
      <origin
        xyz="1.11022302462516E-16 0.0257257525083613 -8.32667268468867E-17"
        rpy="0 0 0" />
      <mass
        value="4.40470068076377" />
      <inertia
        ixx="0.000245137261047142"
        ixy="5.12745004835681E-20"
        ixz="0"
        iyy="0.000452624182450971"
        iyz="-5.57841424911612E-20"
        izz="0.000245137261047142" />
    </inertial>
    <visual>
      <origin
        xyz="0 0 0"
        rpy="0 0 0" />
      <geometry>
        <mesh
          filename="file:///$(find my_robot_description)/meshes/diffdrive_meshes/Wheel_left.STL" />
      </geometry>
      <material
        name="">
        <color
          rgba="0.792156862745098 0.819607843137255 0.933333333333333 1" />
      </material>
    </visual>
    <collision>
      <origin
        xyz="0 0 0"
        rpy="0 0 0" />
      <geometry>
        <mesh
          filename="file:///$(find my_robot_description)/meshes/diffdrive_meshes/Wheel_left.STL" />
      </geometry>
    </collision>
  </link>
  <joint
    name="left_wheel_joint"
    type="continuous">
    <origin
      xyz="-0.000999999999839296 -0.249999999999933 0.0305000000006919"
      rpy="0 0.774914173734372 3.14159265358979" />
    <parent
      link="base_link_diff" />
    <child
      link="Wheel_left" />
    <axis
      xyz="0 1 0" />
  </joint>
  <link
    name="Wheel_right">
    <inertial>
      <origin
        xyz="-1.38777878078145E-16 0.0257257525084522 5.55111512312578E-17"
        rpy="0 0 0" />
      <mass
        value="4.40470068076377" />
      <inertia
        ixx="0.000245137261047143"
        ixy="5.77297627993884E-21"
        ixz="1.35525271560688E-20"
        iyy="0.000452624182450972"
        iyz="1.29229555498199E-20"
        izz="0.000245137261047143" />
    </inertial>
    <visual>
      <origin
        xyz="0 0 0"
        rpy="0 0 0" />
      <geometry>
        <mesh
          filename="file:///$(find my_robot_description)/meshes/diffdrive_meshes/Wheel_right.STL" />
      </geometry>
      <material
        name="">
        <color
          rgba="0.792156862745098 0.819607843137255 0.933333333333333 1" />
      </material>
    </visual>
    <collision>
      <origin
        xyz="0 0 0"
        rpy="0 0 0" />
      <geometry>
        <mesh
          filename="file:///$(find my_robot_description)/meshes/diffdrive_meshes/Wheel_right.STL" />
      </geometry>
    </collision>
  </link>
  <joint
    name="right_wheel_joint"
    type="continuous">
    <origin
      xyz="-0.000999999999862333 0.250000000000088 0.0305000000006919"
      rpy="3.14159265358979 -0.53712555837446 3.14159265358979" />
    <parent
      link="base_link_diff" />
    <child
      link="Wheel_right" />
    <axis
      xyz="0 -1 0" />
  </joint>
  <link
    name="folk_diff_right">
    <inertial>
      <origin
        xyz="0.25796 -0.0675 0.01"
        rpy="0 0 0" />
      <mass
        value="0.052454" />
      <inertia
        ixx="4.2123E-05"
        ixy="1.618E-18"
        ixz="-1.9029E-14"
        iyy="0.013244"
        iyz="2.3396E-16"
        izz="0.013244" />
    </inertial>
    <visual>
      <origin
        xyz="0 0 0"
        rpy="0 0 0" />
      <geometry>
        <mesh
          filename="file:///$(find my_robot_description)/meshes/diffdrive_meshes/folk_right.STL" />
      </geometry>
      <material
        name="">
        <color
          rgba="0 1 0 0.5" />
      </material>
    </visual>
    <collision>
      <origin
        xyz="0.25796 0.0675 0.01"
        rpy="0.0 0.0 0.0" />
        <geometry>
            <box size="0.55 0.04 0.02"/>
        </geometry> 
     <surface>
        <poissons_ratio>0.347</poissons_ratio>
        <elastic_modulus>8.8e+09</elastic_modulus>
        <ode>
          <soft_cfm>2e+20</soft_cfm>
          <soft_erp>2e+40</soft_erp>
          <kp>1000</kp>
          <kd>1</kd>
          <max_vel>0.01</max_vel>
          <min_depth>1.0</min_depth>
        </ode>
      </surface>
    </collision>
  </link>
  <joint
    name="folk_diff_right_fixed"
    type="fixed">
    <origin
      xyz="-0.107035355338993 0 0.120000000000272"
      rpy="0 0 -3.14159265358979" />
    <parent
      link="base_link_diff" />
    <child
      link="folk_diff_right" />
    <axis
      xyz="0 0 0" />
  </joint>
  <link
    name="folk_diff_left">
    <inertial>
      <origin
        xyz="0.25796 0.0675 0.01"
        rpy="0 0 0" />
      <mass
        value="0.052454" />
      <inertia
        ixx="4.2123E-05"
        ixy="1.618E-18"
        ixz="-1.9029E-14"
        iyy="0.013244"
        iyz="2.3396E-16"
        izz="0.013244" />
    </inertial>
    <visual>
      <origin
        xyz="0 0 0"
        rpy="0 0 0" />
      <geometry>
        <mesh
          filename="file:///$(find my_robot_description)/meshes/diffdrive_meshes/folk_left.STL" />
      </geometry>
      <material
        name="">
        <color
          rgba="0 0.5 0 0.5" />
      </material>
    </visual>
    <collision>
      <origin
        xyz="0.25796 0.0675 0.01"
        rpy="0.0 0.0 0.0" />
        <geometry>
            <box size="0.55 0.04 0.02"/>
        </geometry> 
     <surface>
        <poissons_ratio>0.347</poissons_ratio>
        <elastic_modulus>8.8e+09</elastic_modulus>
        <ode>
          <soft_cfm>2e+20</soft_cfm>
          <soft_erp>2e+40</soft_erp>
          <kp>1000</kp>
          <kd>1</kd>
          <max_vel>0.01</max_vel>
          <min_depth>1.0</min_depth>
        </ode>
      </surface>
    </collision>
  </link>
  <joint
    name="folk_diff_left_fixed"
    type="fixed">
    <origin
      xyz="-0.107035355338993 0 0.120000000000272"
      rpy="0 0 -3.14159265358979" />
    <parent
      link="base_link_diff" />
    <child
      link="folk_diff_left" />
    <axis
      xyz="0 0 0" />
  </joint>

    <gazebo>
        <plugin name="gazebo_ros_diff_drive" filename="libgazebo_ros_diff_drive.so">
            <!-- Update rate in Hz -->
            <ros>
            <!-- Add a namespace -->
            <namespace>diff</namespace>
             <remapping>/diff/cmd_vel:=/cmd_vel_follower</remapping>
            </ros>
            <update_rate>50</update_rate>
            <!-- wheels -->
            <left_joint>left_wheel_joint</left_joint>
            <right_joint>right_wheel_joint</right_joint>
            <!-- kinematics -->
            <wheel_separation>0.5</wheel_separation>
            <wheel_diameter>0.12</wheel_diameter>
            <!-- input -->
            <command_topic>cmd_vel_follower</command_topic>
            <!-- output -->
            <publish_odom>true</publish_odom>
            <!-- Odometry source, 0 for ENCODER, 1 for WORLD, defaults to WORLD -->
            <odometrySource>1</odometrySource>
            <publish_odom_tf>true</publish_odom_tf>
            <publish_wheel_tf>true</publish_wheel_tf>
            <odometry_topic>diffdrive/odom</odometry_topic>
            <odometry_frame>diff_odom</odometry_frame>
            <robot_base_frame>base_footprint_diff</robot_base_frame>
        </plugin>
    </gazebo>

    <gazebo reference="wheel_right">
      <material>Gazebo/Green</material>
    </gazebo>

    <gazebo reference="wheel_left">
      <material>Gazebo/Green</material>
    </gazebo>
    
    <gazebo reference="base_link_diff">
      <material>Gazebo/White</material>
    </gazebo>


    <gazebo reference="laser_frame_diff">
        <material>Gazebo/Black</material>

        <sensor name="laser" type="ray">
            <pose> 0 0 0 0 0 0 </pose>
            <visualize>false</visualize>
            <update_rate>10</update_rate>
            <ray>
                <scan>
                    <horizontal>
                        <samples>360</samples>
                        <min_angle>-3.14</min_angle>
                        <max_angle>3.14</max_angle>
                    </horizontal>
                </scan>
                <range>
                    <min>0.3</min>
                    <max>12</max>
                </range>
            </ray>
            <plugin name="laser_controller_diff" filename="libgazebo_ros_ray_sensor.so">
                <ros>
                    <argument>~/out:=scan_diff</argument>
                </ros>
                <output_type>sensor_msgs/LaserScan</output_type>
                <frame_name>laser_frame_diff</frame_name>
            </plugin>
        </sensor>
    </gazebo>


</robot>