<?xml version="1.0"?>
<robot xmlns:xacro="http://www.ros.org/wiki/xacro" name="diffdrive2" >
<!-- This URDF was automatically created by SolidWorks to URDF Exporter! Originally created by Stephen Brawner (brawner@gmail.com) 
     Commit Version: 1.6.0-4-g7f85cfe  Build Version: 1.6.7995.38578
     For more information, please see http://wiki.ros.org/sw_urdf_exporter -->
  <link name="base_footprint"></link>
  <joint name="base_link_to_base_footprint" type="fixed">
    <origin xyz="0 0 0" rpy="0 0 0"/>
    <parent link="base_footprint"/>
    <child link="base_link"/>
  </joint>

  <link name="laser_frame">
    <visual>
      <geometry>
        <cylinder radius="0.05" length="0.04"/>
      </geometry>
    </visual>
    <collision>
      <geometry>
        <cylinder radius="0.05" length="0.04"/>
      </geometry>
    </collision>
      <inertial>
      <origin
        xyz="0 0 0"
        rpy="0 0 0" />
      <mass
        value="0.1" />
      <inertia
        ixx="0.01" ixy="0.0" ixz="0.0"
        iyy="0.01" iyz="0.0"
        izz="0.01"/>
    </inertial>
  </link>

  <joint name="laser_joint" type="fixed">
    <origin xyz="0 0 0.12" rpy="0 0 0"/>
    <parent link="base_link"/>
    <child link="laser_frame"/>
  </joint>

  <link
    name="base_link">
    <inertial>
      <origin
        xyz="-0.00843797932248264 7.91524717263514E-05 0.0510944704707574"
        rpy="0 0 0" />
      <mass
        value="4.20115624935193" />
      <inertia
        ixx="0.0441950216113175"
        ixy="-6.1273841754346E-08"
        ixz="1.5363609769836E-06"
        iyy="0.0338853571996096"
        iyz="2.75308042467669E-07"
        izz="0.077237000418039" />
    </inertial>
    <visual>
      <origin
        xyz="0 0 0"
        rpy="0 0 0" />
      <geometry>
        <mesh
          filename="file:///$(find my_robot_description)/meshes/diffdrive_meshes/base_link.STL" />
      </geometry>
      <material
        name="">
        <color
          rgba="0.752941176470588 0.752941176470588 0.752941176470588 1" />
      </material>
    </visual>
    <collision>
      <origin
        xyz="0 0 0"
        rpy="0 0 0" />
      <geometry>
        <mesh
          filename="file:///$(find my_robot_description)/meshes/diffdrive_meshes/base_link.STL" />
      </geometry>
    </collision>
  </link>
  <link
    name="Wheel_left">
    <inertial>
      <origin
        xyz="0 0.0257257525083612 -2.77555756156289E-17"
        rpy="0 0 0" />
      <mass
        value="0.240470068076377" />
      <inertia
        ixx="0.000245137261047142"
        ixy="5.12745004835681E-20"
        ixz="0"
        iyy="0.000452624182450971"
        iyz="-5.57841424911612E-20"
        izz="0.000245137261047142" />
    </inertial>
    <visual>
      <origin
        xyz="0 0 0"
        rpy="0 0 0" />
      <geometry>
        <mesh
          filename="file:///$(find my_robot_description)/meshes/diffdrive_meshes/Wheel_left.STL" />
      </geometry>
      <material
        name="">
        <color
          rgba="0.792156862745098 0.819607843137255 0.933333333333333 1" />
      </material>
    </visual>
    <collision>
      <origin
        xyz="0 0 0"
        rpy="0 0 0" />
      <geometry>
        <mesh
          filename="file:///$(find my_robot_description)/meshes/diffdrive_meshes/Wheel_left.STL" />
      </geometry>
    </collision>
  </link>
  <joint
    name="right_wheel_joint"
    type="continuous">
    <origin
      xyz="-0.000999999999839296 -0.249999999999933 0.0305000000006919"
      rpy="0 0.774914173734372 3.14159265358979" />
    <parent
      link="base_link" />
    <child
      link="Wheel_left" />
    <axis
      xyz="0 -1 0" />
  </joint>
  <link
    name="Wheel_right">
    <inertial>
      <origin
        xyz="5.55111512312578E-17 0.0257257525083612 5.55111512312578E-17"
        rpy="0 0 0" />
      <mass
        value="0.240470068076377" />
      <inertia
        ixx="0.000245137261047143"
        ixy="4.26861241081053E-21"
        ixz="-6.7762635780344E-21"
        iyy="0.000452624182450972"
        iyz="1.59972478988236E-20"
        izz="0.000245137261047143" />
    </inertial>
    <visual>
      <origin
        xyz="0 0 0"
        rpy="0 0 0" />
      <geometry>
        <mesh
          filename="file:///$(find my_robot_description)/meshes/diffdrive_meshes/Wheel_right.STL" />
      </geometry>
      <material
        name="">
        <color
          rgba="0.792156862745098 0.819607843137255 0.933333333333333 1" />
      </material>
    </visual>
    <collision>
      <origin
        xyz="0 0 0"
        rpy="0 0 0" />
      <geometry>
        <mesh
          filename="file:///$(find my_robot_description)/meshes/diffdrive_meshes/Wheel_right.STL" />
      </geometry>
    </collision>
  </link>
  <joint
    name="left_wheel_joint"
    type="continuous">
    <origin
      xyz="-0.000999999999862333 0.250000000000088 0.0305000000006919"
      rpy="3.14159265358979 -0.53712555837446 3.14159265358979" />
    <parent
      link="base_link" />
    <child
      link="Wheel_right" />
    <axis
      xyz="0 1 0" />
  </joint>

    <gazebo>
        <plugin name="gazebo_ros_diff_drive" filename="libgazebo_ros_diff_drive.so">
            <!-- Update rate in Hz -->
            <ros>
            <!-- Add a namespace -->
            <namespace></namespace>
            </ros>
            <update_rate>50</update_rate>
            <!-- wheels -->
            <left_joint>left_wheel_joint</left_joint>
            <right_joint>right_wheel_joint</right_joint>
            <!-- kinematics -->
            <wheel_separation>0.5</wheel_separation>
            <wheel_diameter>0.12</wheel_diameter>
            <!-- input -->
            <command_topic>cmd_vel</command_topic>
            <!-- output -->
            <publish_odom>true</publish_odom>
            <!-- Odometry source, 0 for ENCODER, 1 for WORLD, defaults to WORLD -->
            <odometrySource>1</odometrySource>
            <publish_odom_tf>true</publish_odom_tf>
            <publish_wheel_tf>true</publish_wheel_tf>
            <odometry_topic>diffdrive/odom</odometry_topic>
            <odometry_frame>odom</odometry_frame>
            <robot_base_frame>base_footprint</robot_base_frame>
        </plugin>
    </gazebo>

    <gazebo reference="laser_frame">
        <material>Gazebo/Red</material>

        <sensor name="laser" type="ray">
            <pose> 0 0 0 0 0 0 </pose>
            <visualize>true</visualize>
            <update_rate>10</update_rate>
            <ray>
                <scan>
                    <horizontal>
                        <samples>360</samples>
                        <min_angle>-3.14</min_angle>
                        <max_angle>3.14</max_angle>
                    </horizontal>
                </scan>
                <range>
                    <min>0.3</min>
                    <max>12</max>
                </range>
            </ray>
            <plugin name="laser_controller" filename="libgazebo_ros_ray_sensor.so">
                <ros>
                    <argument>~/out:=scan</argument>
                </ros>
                <output_type>sensor_msgs/LaserScan</output_type>
                <frame_name>laser_frame</frame_name>
            </plugin>
        </sensor>
    </gazebo>
</robot>