<?xml version="1.0" encoding="utf-8"?>
<!-- This URDF was automatically created by SolidWorks to URDF Exporter! Originally created by Stephen Brawner (brawner@gmail.com) 
     Commit Version: 1.6.0-4-g7f85cfe  Build Version: 1.6.7995.38578
     For more information, please see http://wiki.ros.org/sw_urdf_exporter -->
<robot
  name="DiffDrive">
  <link
    name="base_link">
    <inertial>
      <origin
        xyz="-0.0869142752472917 -5.31627895317133E-07 0.0703814689792023"
        rpy="0 0 0" />
      <mass
        value="5.71629354062788" />
      <inertia
        ixx="0.0542318682602053"
        ixy="-6.12738449440502E-08"
        ixz="1.53636097102655E-06"
        iyy="0.060410631409919"
        iyz="6.21772232515673E-09"
        izz="0.113677691165547" />
    </inertial>
    <visual>
      <origin
        xyz="0 0 0"
        rpy="0 0 0" />
      <geometry>
        <mesh
          filename="package://DiffDrive/meshes/base_link.STL" />
      </geometry>
      <material
        name="">
        <color
          rgba="0.752941176470588 0.752941176470588 0.752941176470588 1" />
      </material>
    </visual>
    <collision>
      <origin
        xyz="0 0 0"
        rpy="0 0 0" />
      <geometry>
        <mesh
          filename="package://DiffDrive/meshes/base_link.STL" />
      </geometry>
    </collision>
  </link>
  <link
    name="Wheel_left">
    <inertial>
      <origin
        xyz="1.11022302462516E-16 0.0257257525083612 -1.11022302462516E-16"
        rpy="0 0 0" />
      <mass
        value="0.240470068076377" />
      <inertia
        ixx="0.000245137261047143"
        ixy="5.12745004835681E-20"
        ixz="0"
        iyy="0.000452624182450971"
        iyz="-5.57841424911612E-20"
        izz="0.000245137261047143" />
    </inertial>
    <visual>
      <origin
        xyz="0 0 0"
        rpy="0 0 0" />
      <geometry>
        <mesh
          filename="package://DiffDrive/meshes/Wheel_left.STL" />
      </geometry>
      <material
        name="">
        <color
          rgba="0.792156862745098 0.819607843137255 0.933333333333333 1" />
      </material>
    </visual>
    <collision>
      <origin
        xyz="0 0 0"
        rpy="0 0 0" />
      <geometry>
        <mesh
          filename="package://DiffDrive/meshes/Wheel_left.STL" />
      </geometry>
    </collision>
  </link>
  <joint
    name="Joint_left"
    type="continuous">
    <origin
      xyz="-0.000999999999839296 -0.249999999999933 0.0305000000006919"
      rpy="0 0.774914173734372 3.14159265358979" />
    <parent
      link="base_link" />
    <child
      link="Wheel_left" />
    <axis
      xyz="0 1 0" />
  </joint>
  <link
    name="Wheel_right">
    <inertial>
      <origin
        xyz="-1.38777878078145E-16 0.0257257525083612 5.55111512312578E-17"
        rpy="0 0 0" />
      <mass
        value="0.240470068076377" />
      <inertia
        ixx="0.000245137261047143"
        ixy="5.77297627993884E-21"
        ixz="1.35525271560688E-20"
        iyy="0.000452624182450972"
        iyz="1.29229555498199E-20"
        izz="0.000245137261047143" />
    </inertial>
    <visual>
      <origin
        xyz="0 0 0"
        rpy="0 0 0" />
      <geometry>
        <mesh
          filename="package://DiffDrive/meshes/Wheel_right.STL" />
      </geometry>
      <material
        name="">
        <color
          rgba="0.792156862745098 0.819607843137255 0.933333333333333 1" />
      </material>
    </visual>
    <collision>
      <origin
        xyz="0 0 0"
        rpy="0 0 0" />
      <geometry>
        <mesh
          filename="package://DiffDrive/meshes/Wheel_right.STL" />
      </geometry>
    </collision>
  </link>
  <joint
    name="Joint_right"
    type="continuous">
    <origin
      xyz="-0.000999999999862333 0.250000000000088 0.0305000000006919"
      rpy="3.14159265358979 -0.53712555837446 3.14159265358979" />
    <parent
      link="base_link" />
    <child
      link="Wheel_right" />
    <axis
      xyz="0 1 0" />
  </joint>
</robot>