<?xml version="1.0"?>
<robot xmlns:xacro="http://www.ros.org/wiki/xacro" name="ackermann" >
  <link name="base_footprint_ack">
  </link>
  <joint name="base_link_ack_to_base_footprint_ack" type="fixed">
    <origin xyz="0 0 0.12" rpy="0 0 0"/>
    <parent link="base_footprint_ack"/>
    <child link="base_link"/>
  </joint>

  <link
    name="base_link">
    <inertial>
      <origin
        xyz="-0.0651994405179663 4.22434509872449E-07 -0.0239634712761258"
        rpy="0 0 0" />
      <mass
        value="1.25555128497609" />
      <inertia
        ixx="0.0414328478617682"
        ixy="-1.82796488685318E-07"
        ixz="3.45960820664179E-07"
        iyy="0.0417152661425413"
        iyz="1.05010040923958E-07"
        izz="0.0821338918053197" />
    </inertial>
    <visual>
      <origin
        xyz="0 0 0"
        rpy="0 0 0" />
      <geometry>
        <mesh
          filename="file:///$(find my_robot_description)/meshes/ackermann_meshes/base_link.STL" />
      </geometry>
      <material
        name="">
        <color
          rgba="1 1 1 0.4" />
      </material>
    </visual>
    <collision>
      <origin
        xyz="0 0 0"
        rpy="0 0 0" />
      <geometry>
        <mesh
          filename="file:///$(find my_robot_description)/meshes/ackermann_meshes/base_link.STL" />
      </geometry>
    </collision>
  </link>
  <link
    name="front_left">
    <inertial>
      <origin
        xyz="3.8858E-15 -0.015274 4.6435E-14"
        rpy="0 0 0" />
      <mass
        value="0.24047" />
      <inertia
        ixx="0.00024514"
        ixy="5.4339E-21"
        ixz="-6.7763E-21"
        iyy="0.00045262"
        iyz="6.4709E-20"
        izz="0.00024514" />
    </inertial>
    <visual>
      <origin
        xyz="0 0 0"
        rpy="0 0 0" />
      <geometry>
        <mesh
          filename="file:///$(find my_robot_description)/meshes/ackermann_meshes/front_left.STL" />
      </geometry>
      <material
        name="">
        <color
          rgba="0 1 0 0.5" />
      </material>
    </visual>
    <collision>
      <origin
        xyz="0 0 0"
        rpy="0 0 0" />
      <geometry>
        <mesh
          filename="file:///$(find my_robot_description)/meshes/ackermann_meshes/front_left.STL" />
      </geometry>
    </collision>
  </link>
  <joint
    name="front_left_joint"
    type="continuous">
    <origin
      xyz="0.0190000000000679 0.301000000000045 -0.0695000000000887"
      rpy="3.14159265358979 0.0849179307157281 3.14159265358979" />
    <parent
      link="base_link" />
    <child
      link="front_left" />
    <axis
      xyz="0 1 0" />
  </joint>
  <link
    name="front_right">
    <inertial>
      <origin
        xyz="-2.9643E-14 0.025726 3.5749E-14"
        rpy="0 0 0" />
      <mass
        value="0.24047" />
      <inertia
        ixx="0.00024514"
        ixy="5.2554E-21"
        ixz="0"
        iyy="0.00045262"
        iyz="4.3994E-20"
        izz="0.00024514" />
    </inertial>
    <visual>
      <origin
        xyz="0 0 0"
        rpy="0 0 0" />
      <geometry>
        <mesh
          filename="file:///$(find my_robot_description)/meshes/ackermann_meshes/front_right.STL" />
      </geometry>
      <material
        name="">
        <color
          rgba="0 1 0 0.5" />
      </material>
    </visual>
    <collision>
      <origin
        xyz="0 0 0"
        rpy="0 0 0" />
      <geometry>
        <mesh
          filename="file:///$(find my_robot_description)/meshes/ackermann_meshes/front_right.STL" />
      </geometry>
    </collision>
  </link>
  <joint
    name="front_right_joint"
    type="continuous">
    <origin
      xyz="0.0190000000000679 -0.259999999999977 -0.0695000000000887"
      rpy="3.14159265358979 -0.692237011731428 0" />
    <parent
      link="base_link" />
    <child
      link="front_right" />
    <axis
      xyz="0 1 0" />
  </joint>
  <link
    name="left_steering">
    <inertial>
      <origin
        xyz="0.0121532099874294 -0.0166916241895938 -0.0211847288398316"
        rpy="0 0 0" />
      <mass
        value="0.0405602056975407" />
      <inertia
        ixx="1.43958495481578E-05"
        ixy="-1.73339990683825E-06"
        ixz="-7.11935154287877E-06"
        iyy="2.95171085845272E-05"
        iyz="2.08772590818048E-06"
        izz="3.10994722329793E-05" />
    </inertial>
    <visual>
      <origin
        xyz="0 0 0"
        rpy="0 0 0" />
      <geometry>
        <mesh
          filename="file:///$(find my_robot_description)/meshes/ackermann_meshes/left_steering.STL" />
      </geometry>
      <material
        name="">
        <color
          rgba="0.792156862745098 0.819607843137255 0.933333333333333 1" />
      </material>
    </visual>
    <collision>
      <origin
        xyz="0 0 0"
        rpy="0 0 0" />
      <geometry>
        <mesh
          filename="file:///$(find my_robot_description)/meshes/ackermann_meshes/left_steering.STL" />
      </geometry>
    </collision>
  </link>
  <joint
    name="left_steering_joint"
    type="continuous">
    <origin
      xyz="-0.544750000000063 0.229999999999977 -0.0837500000002837"
      rpy="3.14159265358979 0 -0.00209254658538632" />
    <parent
      link="base_link" />
    <child
      link="left_steering" />
    <axis
      xyz="0 0 1" />
  </joint>
  <link
    name="rear_left">
    <inertial>
      <origin
        xyz="-1.5192E-06 0.025619 0.006692"
        rpy="0 0 0" />
      <mass
        value="0.24047" />
      <inertia
        ixx="0.00024514"
        ixy="-4.9967E-09"
        ixz="-5.3615E-10"
        iyy="0.00045026"
        iyz="2.201E-05"
        izz="0.0002475" />
    </inertial>
    <visual>
      <origin
        xyz="0 0 0"
        rpy="0 0 0" />
      <geometry>
        <mesh
          filename="file:///$(find my_robot_description)/meshes/ackermann_meshes/rear_left.STL" />
      </geometry>
      <material
        name="">
        <color
          rgba="0 1 0 0.5" />
      </material>
    </visual>
    <collision>
      <origin
        xyz="0 0 0"
        rpy="0 0 0" />
      <geometry>
        <mesh
          filename="file:///$(find my_robot_description)/meshes/ackermann_meshes/rear_left.STL" />
      </geometry>
    </collision>
  </link>
  <joint
    name="rear_left_joint"
    type="continuous">
    <origin
      xyz="0 -0.0367488381424265 -0.0159999999999999"
      rpy="3.14159265358979 1.57056930363849 0" />
    <parent
      link="left_steering" />
    <child
      link="rear_left" />
    <axis
      xyz="0 1 0" />
  </joint>
  <link
    name="right_steering">
    <inertial>
      <origin
        xyz="-0.0138648104691156 -0.0152975676601856 -0.021184728839829"
        rpy="0 0 0" />
      <mass
        value="0.0405602056975408" />
      <inertia
        ixx="1.49389187707206E-05"
        ixy="3.30295116006257E-06"
        ixz="7.3015684371967E-06"
        iyy="2.89780797923847E-05"
        iyz="1.31491150207248E-06"
        izz="3.11035126633983E-05" />
    </inertial>
    <visual>
      <origin
        xyz="0 0 0"
        rpy="0 0 0" />
      <geometry>
        <mesh
          filename="file:///$(find my_robot_description)/meshes/ackermann_meshes/right_steering.STL" />
      </geometry>
      <material
        name="">
        <color
          rgba="0.792156862745098 0.819607843137255 0.933333333333333 1" />
      </material>
    </visual>
    <collision>
      <origin
        xyz="0 0 0"
        rpy="0 0 0" />
      <geometry>
        <mesh
          filename="file:///$(find my_robot_description)/meshes/ackermann_meshes/right_steering.STL" />
      </geometry>
    </collision>
  </link>
  <joint
    name="right_steering_joint"
    type="continuous">
    <origin
      xyz="-0.544750000000063 -0.230000000000023 -0.0837500000002836"
      rpy="3.14159265358979 0 -3.13242627228221" />
    <parent
      link="base_link" />
    <child
      link="right_steering" />
    <axis
      xyz="0 0 1" />
  </joint>
  <link
    name="rear_right">
    <inertial>
      <origin
        xyz="1.415E-10 0.025722 1.2793E-08"
        rpy="0 0 0" />
      <mass
        value="0.24047" />
      <inertia
        ixx="0.00024514"
        ixy="4.6696E-13"
        ixz="9.4021E-20"
        iyy="0.00045262"
        iyz="4.2319E-11"
        izz="0.00024514" />
    </inertial>
    <visual>
      <origin
        xyz="0 0 0"
        rpy="0 0 0" />
      <geometry>
        <mesh
          filename="file:///$(find my_robot_description)/meshes/ackermann_meshes/rear_right.STL" />
      </geometry>
      <material
        name="">
        <color
          rgba="0 1 0 0.5" />
      </material>
    </visual>
    <collision>
      <origin
        xyz="0 0 0"
        rpy="0 0 0" />
      <geometry>
        <mesh
          filename="file:///$(find my_robot_description)/meshes/ackermann_meshes/rear_right.STL" />
      </geometry>
    </collision>
  </link>
  <joint
    name="rear_right_joint"
    type="continuous">
    <origin
      xyz="0 -0.0370034448281129 -0.0159999999999995"
      rpy="3.14159265358979 -1.55976234848309 0" />
    <parent
      link="right_steering" />
    <child
      link="rear_right" />
    <axis
      xyz="0 1 0" />
  </joint>

 <gazebo>
    <plugin name="gazebo_ros_ackermann_drive" filename="libgazebo_ros_ackermann_drive.so">
      <ros>
        <namespace>/ackermann</namespace>
      </ros>

      <update_rate>100.0</update_rate>


      <wheel_base>0.65</wheel_base>
      <wheel_separation>0.55</wheel_separation>
      <wheel_radius>0.06</wheel_radius>

      <!-- wheels -->
      <front_left_joint>rear_right_joint</front_left_joint>
      <front_right_joint>rear_left_joint</front_right_joint>
      <rear_left_joint>front_right_joint</rear_left_joint>
      <rear_right_joint>front_left_joint</rear_right_joint>

      <!-- wheels -->
      <!-- <front_left_joint>front_left_joint</front_left_joint>
      <front_right_joint>front_right_joint</front_right_joint>
      <rear_left_joint>rear_left_joint</rear_left_joint>
      <rear_right_joint>rear_right_joint</rear_right_joint> -->

      <!-- steering joints -->
      <left_steering_joint>right_steering_joint</left_steering_joint>
      <right_steering_joint>left_steering_joint</right_steering_joint>

      <!-- Max absolute steer angle for tyre in radians-->
      <!-- Any cmd_vel angular z greater than this would be capped -->
      <max_steer>0.6458</max_steer>

      <!-- Max absolute steering angle of steering wheel -->
      <max_steering_angle>7.85</max_steering_angle>

      <!-- Max absolute linear speed in m/s -->
      <max_speed>20</max_speed>

      <!-- PID tuning -->
      <left_steering_pid_gain>1 0 1</left_steering_pid_gain>
      <left_steering_i_range>0 0</left_steering_i_range>
      <right_steering_pid_gain>1 0 1</right_steering_pid_gain>
      <right_steering_i_range>0 0</right_steering_i_range>
      <linear_velocity_pid_gain>1000 0 1</linear_velocity_pid_gain>
      <linear_velocity_i_range>0 0</linear_velocity_i_range>

      <!-- output -->
      <publish_odom>true</publish_odom>
      <publish_odom_tf>true</publish_odom_tf>
      <publish_wheel_tf>true</publish_wheel_tf>
      <publish_distance>true</publish_distance>

      <odometry_frame>odom_ack</odometry_frame>
      <robot_base_frame>base_link</robot_base_frame>
    </plugin>
  </gazebo>
</robot>