<?xml version="1.0" encoding="utf-8"?>
<!-- This URDF was automatically created by SolidWorks to URDF Exporter! Originally created by Stephen Brawner (brawner@gmail.com) 
     Commit Version: 1.6.0-4-g7f85cfe  Build Version: 1.6.7995.38578
     For more information, please see http://wiki.ros.org/sw_urdf_exporter -->
<robot
  name="Macanum">
  <link
    name="base_link">
    <inertial>
      <origin
        xyz="-1.61616945937304E-08 0.129846942362491 -0.00882744639139549"
        rpy="0 0 0" />
      <mass
        value="3.34194808867752" />
      <inertia
        ixx="0.0577028852618912"
        ixy="5.10376118114746E-19"
        ixz="-5.64437511179871E-14"
        iyy="0.0133555177325467"
        iyz="-4.93932954401171E-08"
        izz="0.0706136642111468" />
    </inertial>
    <visual>
      <origin
        xyz="0 0 0"
        rpy="0 0 0" />
      <geometry>
        <mesh
          filename="package://Macanum/meshes/base_link.STL" />
      </geometry>
      <material
        name="">
        <color
          rgba="0.898039215686275 0.917647058823529 0.929411764705882 1" />
      </material>
    </visual>
    <collision>
      <origin
        xyz="0 0 0"
        rpy="0 0 0" />
      <geometry>
        <mesh
          filename="package://Macanum/meshes/base_link.STL" />
      </geometry>
    </collision>
  </link>
  <link
    name="wheel_fr_right">
    <inertial>
      <origin
        xyz="1.66533453693773E-16 3.33066907387547E-16 -0.0264473304136223"
        rpy="0 0 0" />
      <mass
        value="0.321375664058358" />
      <inertia
        ixx="9.13370307716643E-05"
        ixy="-1.71206096476264E-18"
        ixz="4.25293504226191E-18"
        iyy="9.13370307716681E-05"
        iyz="7.83107768630978E-17"
        izz="0.00011244499645403" />
    </inertial>
    <visual>
      <origin
        xyz="0 0 0"
        rpy="0 0 0" />
      <geometry>
        <mesh
          filename="package://Macanum/meshes/wheel_fr_right.STL" />
      </geometry>
      <material
        name="">
        <color
          rgba="0.776470588235294 0.756862745098039 0.737254901960784 1" />
      </material>
    </visual>
    <collision>
      <origin
        xyz="0 0 0"
        rpy="0 0 0" />
      <geometry>
        <mesh
          filename="package://Macanum/meshes/wheel_fr_right.STL" />
      </geometry>
    </collision>
  </link>
  <joint
    name="joint_fr_right"
    type="continuous">
    <origin
      xyz="0.195390712673452 0.172500000000024 -0.0860000000000467"
      rpy="1.5707963267949 0 1.5707963267949" />
    <parent
      link="base_link" />
    <child
      link="wheel_fr_right" />
    <axis
      xyz="0 0 -1" />
  </joint>
  <link
    name="wheel_bk_right">
    <inertial>
      <origin
        xyz="-6.66133814775094E-16 -3.33066907387547E-16 -0.0264473304136224"
        rpy="0 0 0" />
      <mass
        value="0.321375664058357" />
      <inertia
        ixx="9.13370307716783E-05"
        ixy="2.71841191269208E-19"
        ixz="1.52110311274399E-19"
        iyy="9.13370307716787E-05"
        iyz="-7.65179549286359E-17"
        izz="0.000112444996454044" />
    </inertial>
    <visual>
      <origin
        xyz="0 0 0"
        rpy="0 0 0" />
      <geometry>
        <mesh
          filename="package://Macanum/meshes/wheel_bk_right.STL" />
      </geometry>
      <material
        name="">
        <color
          rgba="0.776470588235294 0.756862745098039 0.737254901960784 1" />
      </material>
    </visual>
    <collision>
      <origin
        xyz="0 0 0"
        rpy="0 0 0" />
      <geometry>
        <mesh
          filename="package://Macanum/meshes/wheel_bk_right.STL" />
      </geometry>
    </collision>
  </link>
  <joint
    name="joint_bk_right"
    type="continuous">
    <origin
      xyz="0.195390712673452 -0.192499999999931 -0.0860000000000467"
      rpy="-1.5707963267949 0 -1.5707963267949" />
    <parent
      link="base_link" />
    <child
      link="wheel_bk_right" />
    <axis
      xyz="0 0 -1" />
  </joint>
  <link
    name="wheel_fr_left">
    <inertial>
      <origin
        xyz="-4.44089209850063E-16 -5.55111512312578E-17 -0.0264433822598774"
        rpy="0 0 0" />
      <mass
        value="0.321375664058357" />
      <inertia
        ixx="9.13370307716802E-05"
        ixy="-6.43331456068013E-19"
        ixz="-3.06962116858911E-19"
        iyy="9.13370307716807E-05"
        iyz="-7.44183078235227E-17"
        izz="0.000112444996454046" />
    </inertial>
    <visual>
      <origin
        xyz="0 0 0"
        rpy="0 0 0" />
      <geometry>
        <mesh
          filename="package://Macanum/meshes/wheel_fr_left.STL" />
      </geometry>
      <material
        name="">
        <color
          rgba="0.776470588235294 0.756862745098039 0.737254901960784 1" />
      </material>
    </visual>
    <collision>
      <origin
        xyz="0 0 0"
        rpy="0 0 0" />
      <geometry>
        <mesh
          filename="package://Macanum/meshes/wheel_fr_left.STL" />
      </geometry>
    </collision>
  </link>
  <joint
    name="joint_fr_left"
    type="continuous">
    <origin
      xyz="-0.195390712673501 0.172500000000024 -0.086000000000046"
      rpy="1.5707963267949 0 -1.5707963267949" />
    <parent
      link="base_link" />
    <child
      link="wheel_fr_left" />
    <axis
      xyz="0 0 1" />
  </joint>
  <link
    name="wheel_bk_left">
    <inertial>
      <origin
        xyz="-5.55111512312578E-16 -5.55111512312578E-17 -0.026443382259877"
        rpy="0 0 0" />
      <mass
        value="0.321375664058359" />
      <inertia
        ixx="9.13370307716977E-05"
        ixy="1.26284611161912E-18"
        ixz="-5.44780593968537E-18"
        iyy="9.13370307716954E-05"
        iyz="-7.63079098379893E-17"
        izz="0.000112444996454065" />
    </inertial>
    <visual>
      <origin
        xyz="0 0 0"
        rpy="0 0 0" />
      <geometry>
        <mesh
          filename="package://Macanum/meshes/wheel_bk_left.STL" />
      </geometry>
      <material
        name="">
        <color
          rgba="0.776470588235294 0.756862745098039 0.737254901960784 1" />
      </material>
    </visual>
    <collision>
      <origin
        xyz="0 0 0"
        rpy="0 0 0" />
      <geometry>
        <mesh
          filename="package://Macanum/meshes/wheel_bk_left.STL" />
      </geometry>
    </collision>
  </link>
  <joint
    name="joint_bk_left"
    type="continuous">
    <origin
      xyz="-0.195390712673501 -0.192499999999931 -0.086000000000046"
      rpy="1.5707963267949 0 -1.5707963267949" />
    <parent
      link="base_link" />
    <child
      link="wheel_bk_left" />
    <axis
      xyz="0 0 1" />
  </joint>
</robot>