<?xml version="1.0" encoding="utf-8"?>
<!-- This URDF was automatically created by SolidWorks to URDF Exporter! Originally created by Stephen Brawner (brawner@gmail.com) 
     Commit Version: 1.6.0-4-g7f85cfe  Build Version: 1.6.7995.38578
     For more information, please see http://wiki.ros.org/sw_urdf_exporter -->
<robot
  name="DiffDrive_update">
  <link
    name="base_link">
    <inertial>
      <origin
        xyz="0.41 0.22101 0.38486"
        rpy="0 0 0" />
      <mass
        value="4.2012" />
      <inertia
        ixx="0.033885"
        ixy="2.7531E-07"
        ixz="-6.1274E-08"
        iyy="0.077237"
        iyz="1.5364E-06"
        izz="0.044195" />
    </inertial>
    <visual>
      <origin
        xyz="0 0 0"
        rpy="0 0 0" />
      <geometry>
        <mesh
          filename="package://DiffDrive_update/meshes/base_link.STL" />
      </geometry>
      <material
        name="">
        <color
          rgba="0.75294 0.75294 0.75294 1" />
      </material>
    </visual>
    <collision>
      <origin
        xyz="0 0 0"
        rpy="0 0 0" />
      <geometry>
        <mesh
          filename="package://DiffDrive_update/meshes/base_link.STL" />
      </geometry>
    </collision>
  </link>
  <link
    name="Wheel_left">
    <inertial>
      <origin
        xyz="0 0.025726 0"
        rpy="0 0 0" />
      <mass
        value="0.24047" />
      <inertia
        ixx="0.00024514"
        ixy="5.1275E-20"
        ixz="0"
        iyy="0.00045262"
        iyz="-5.5784E-20"
        izz="0.00024514" />
    </inertial>
    <visual>
      <origin
        xyz="0 0 0"
        rpy="0 0 0" />
      <geometry>
        <mesh
          filename="package://DiffDrive_update/meshes/Wheel_left.STL" />
      </geometry>
      <material
        name="">
        <color
          rgba="0.79216 0.81961 0.93333 1" />
      </material>
    </visual>
    <collision>
      <origin
        xyz="0 0 0"
        rpy="0 0 0" />
      <geometry>
        <mesh
          filename="package://DiffDrive_update/meshes/Wheel_left.STL" />
      </geometry>
    </collision>
  </link>
  <joint
    name="Joint_left"
    type="continuous">
    <origin
      xyz="-0.249999999999933 0.0305000000006919 -0.000999999999839241"
      rpy="3.14159265358979 0.795882153060524 -1.5707963267949" />
    <parent
      link="base_link" />
    <child
      link="Wheel_left" />
    <axis
      xyz="0 1 0" />
  </joint>
  <link
    name="Wheel_right">
    <inertial>
      <origin
        xyz="5.5511E-17 0.025726 5.5511E-17"
        rpy="0 0 0" />
      <mass
        value="0.24047" />
      <inertia
        ixx="0.00024514"
        ixy="4.2686E-21"
        ixz="-6.7763E-21"
        iyy="0.00045262"
        iyz="1.5997E-20"
        izz="0.00024514" />
    </inertial>
    <visual>
      <origin
        xyz="0 0 0"
        rpy="0 0 0" />
      <geometry>
        <mesh
          filename="package://DiffDrive_update/meshes/Wheel_right.STL" />
      </geometry>
      <material
        name="">
        <color
          rgba="0.79216 0.81961 0.93333 1" />
      </material>
    </visual>
    <collision>
      <origin
        xyz="0 0 0"
        rpy="0 0 0" />
      <geometry>
        <mesh
          filename="package://DiffDrive_update/meshes/Wheel_right.STL" />
      </geometry>
    </collision>
  </link>
  <joint
    name="Joint_right"
    type="continuous">
    <origin
      xyz="0.250000000000088 0.0305000000006919 -0.000999999999862333"
      rpy="3.14159265358979 1.03367076842044 1.5707963267949" />
    <parent
      link="base_link" />
    <child
      link="Wheel_right" />
    <axis
      xyz="0 1 0" />
  </joint>
</robot>