<?xml version="1.0" encoding="utf-8"?>
<!-- This URDF was automatically created by SolidWorks to URDF Exporter! Originally created by Stephen Brawner (brawner@gmail.com) 
     Commit Version: 1.6.0-4-g7f85cfe  Build Version: 1.6.7995.38578
     For more information, please see http://wiki.ros.org/sw_urdf_exporter -->
<robot
  name="Holonomic">
  <link
    name="base_link">
    <inertial>
      <origin
        xyz="-0.0162517743606357 -0.125779259246447 0.0406114984943946"
        rpy="0 0 0" />
      <mass
        value="7.55917618566118" />
      <inertia
        ixx="0.0520522804369956"
        ixy="-9.40235364052088E-17"
        ixz="-5.71270079519546E-14"
        iyy="0.0387382473112889"
        iyz="-4.93932954490218E-08"
        izz="0.0761652080716073" />
    </inertial>
    <visual>
      <origin
        xyz="0 0 0"
        rpy="0 0 0" />
      <geometry>
        <mesh
          filename="package://Holonomic/meshes/base_link.STL" />
      </geometry>
      <material
        name="">
        <color
          rgba="0.898039215686275 0.917647058823529 0.929411764705882 1" />
      </material>
    </visual>
    <collision>
      <origin
        xyz="0 0 0"
        rpy="0 0 0" />
      <geometry>
        <mesh
          filename="package://Holonomic/meshes/base_link.STL" />
      </geometry>
    </collision>
  </link>
  <link
    name="wheel_fr_right">
    <inertial>
      <origin
        xyz="-3.2357172496944E-12 4.44089209850063E-16 -0.0264473304136224"
        rpy="0 0 0" />
      <mass
        value="0.321375664058357" />
      <inertia
        ixx="9.13370307716739E-05"
        ixy="-1.18507868987411E-19"
        ixz="1.88592248105576E-18"
        iyy="9.13370307716765E-05"
        iyz="7.66936090323006E-17"
        izz="0.00011244499645404" />
    </inertial>
    <visual>
      <origin
        xyz="0 0 0"
        rpy="0 0 0" />
      <geometry>
        <mesh
          filename="package://Holonomic/meshes/wheel_fr_right.STL" />
      </geometry>
      <material
        name="">
        <color
          rgba="0.776470588235294 0.756862745098039 0.737254901960784 1" />
      </material>
    </visual>
    <collision>
      <origin
        xyz="0 0 0"
        rpy="0 0 0" />
      <geometry>
        <mesh
          filename="package://Holonomic/meshes/wheel_fr_right.STL" />
      </geometry>
    </collision>
  </link>
  <joint
    name="joint_fr_right"
    type="continuous">
    <origin
      xyz="0.195390712673444 0.172500000000043 -0.0860000000000453"
      rpy="1.5707963267949 0 1.5707963267949" />
    <parent
      link="base_link" />
    <child
      link="wheel_fr_right" />
    <axis
      xyz="0 0 -1" />
  </joint>
  <link
    name="wheel_bk_right">
    <inertial>
      <origin
        xyz="3.23541193836263E-12 -4.44089209850063E-16 -0.0264473304136225"
        rpy="0 0 0" />
      <mass
        value="0.321375664058357" />
      <inertia
        ixx="9.13370307716793E-05"
        ixy="4.39225623003153E-19"
        ixz="8.09466455494967E-19"
        iyy="9.13370307716796E-05"
        iyz="-7.55583207603397E-17"
        izz="0.000112444996454045" />
    </inertial>
    <visual>
      <origin
        xyz="0 0 0"
        rpy="0 0 0" />
      <geometry>
        <mesh
          filename="package://Holonomic/meshes/wheel_bk_right.STL" />
      </geometry>
      <material
        name="">
        <color
          rgba="0.776470588235294 0.756862745098039 0.737254901960784 1" />
      </material>
    </visual>
    <collision>
      <origin
        xyz="0 0 0"
        rpy="0 0 0" />
      <geometry>
        <mesh
          filename="package://Holonomic/meshes/wheel_bk_right.STL" />
      </geometry>
    </collision>
  </link>
  <joint
    name="joint_bk_right"
    type="continuous">
    <origin
      xyz="0.195390712673444 -0.192499999999912 -0.0860000000000453"
      rpy="-1.5707963267949 0 -1.5707963267949" />
    <parent
      link="base_link" />
    <child
      link="wheel_bk_right" />
    <axis
      xyz="0 0 -1" />
  </joint>
  <link
    name="wheel_fr_left">
    <inertial>
      <origin
        xyz="3.23568949411879E-12 -6.66133814775094E-16 -0.0264433822598773"
        rpy="0 0 0" />
      <mass
        value="0.321375664058358" />
      <inertia
        ixx="9.13370307716825E-05"
        ixy="-8.72325403271903E-19"
        ixz="-7.3690255024894E-19"
        iyy="9.13370307716846E-05"
        iyz="-7.34396237244939E-17"
        izz="0.00011244499645405" />
    </inertial>
    <visual>
      <origin
        xyz="0 0 0"
        rpy="0 0 0" />
      <geometry>
        <mesh
          filename="package://Holonomic/meshes/wheel_fr_left.STL" />
      </geometry>
      <material
        name="">
        <color
          rgba="0.776470588235294 0.756862745098039 0.737254901960784 1" />
      </material>
    </visual>
    <collision>
      <origin
        xyz="0 0 0"
        rpy="0 0 0" />
      <geometry>
        <mesh
          filename="package://Holonomic/meshes/wheel_fr_left.STL" />
      </geometry>
    </collision>
  </link>
  <joint
    name="joint_fr_left"
    type="continuous">
    <origin
      xyz="-0.195390712673509 0.172500000000043 -0.0860000000000444"
      rpy="1.5707963267949 0 -1.5707963267949" />
    <parent
      link="base_link" />
    <child
      link="wheel_fr_left" />
    <axis
      xyz="0 0 1" />
  </joint>
  <link
    name="wheel_bk_left">
    <inertial>
      <origin
        xyz="3.23541193836263E-12 -6.66133814775094E-16 -0.0264433822598771"
        rpy="0 0 0" />
      <mass
        value="0.321375664058358" />
      <inertia
        ixx="9.13370307716971E-05"
        ixy="7.39263638774064E-19"
        ixz="-4.8978063844644E-18"
        iyy="9.13370307716937E-05"
        iyz="-7.54562334477455E-17"
        izz="0.000112444996454064" />
    </inertial>
    <visual>
      <origin
        xyz="0 0 0"
        rpy="0 0 0" />
      <geometry>
        <mesh
          filename="package://Holonomic/meshes/wheel_bk_left.STL" />
      </geometry>
      <material
        name="">
        <color
          rgba="0.776470588235294 0.756862745098039 0.737254901960784 1" />
      </material>
    </visual>
    <collision>
      <origin
        xyz="0 0 0"
        rpy="0 0 0" />
      <geometry>
        <mesh
          filename="package://Holonomic/meshes/wheel_bk_left.STL" />
      </geometry>
    </collision>
  </link>
  <joint
    name="joint_bk_left"
    type="continuous">
    <origin
      xyz="-0.195390712673509 -0.192499999999912 -0.0860000000000444"
      rpy="1.5707963267949 0 -1.5707963267949" />
    <parent
      link="base_link" />
    <child
      link="wheel_bk_left" />
    <axis
      xyz="0 0 1" />
  </joint>
  <link
    name="folk_left">
    <inertial>
      <origin
        xyz="0.177964644657732 0.0675000269663057 0.0100000000001953"
        rpy="0 0 0" />
      <mass
        value="0.524544939385207" />
      <inertia
        ixx="4.21229162907784E-05"
        ixy="-2.23935309384782E-19"
        ixz="4.96407282593822E-18"
        iyy="0.0132439651239293"
        iyz="2.33946512544538E-16"
        izz="0.0132439651530278" />
    </inertial>
    <visual>
      <origin
        xyz="0 0 0"
        rpy="0 0 0" />
      <geometry>
        <mesh
          filename="package://Holonomic/meshes/folk_left.STL" />
      </geometry>
      <material
        name="">
        <color
          rgba="0.898039215686275 0.917647058823529 0.929411764705882 1" />
      </material>
    </visual>
    <collision>
      <origin
        xyz="0 0 0"
        rpy="0 0 0" />
      <geometry>
        <mesh
          filename="package://Holonomic/meshes/folk_left.STL" />
      </geometry>
    </collision>
  </link>
  <joint
    name="folk_left_fixed"
    type="fixed">
    <origin
      xyz="0 0.257035355339075 0"
      rpy="0 0 1.5707963267949" />
    <parent
      link="base_link" />
    <child
      link="folk_left" />
    <axis
      xyz="0 0 0" />
  </joint>
  <link
    name="folk_right">
    <inertial>
      <origin
        xyz="0.177964644657732 -0.0674999730337402 0.0100000000002882"
        rpy="0 0 0" />
      <mass
        value="0.524544939385207" />
      <inertia
        ixx="4.21229162907784E-05"
        ixy="-2.23935447143364E-19"
        ixz="4.96407282593832E-18"
        iyy="0.0132439651239293"
        iyz="2.33946633515815E-16"
        izz="0.0132439651530278" />
    </inertial>
    <visual>
      <origin
        xyz="0 0 0"
        rpy="0 0 0" />
      <geometry>
        <mesh
          filename="package://Holonomic/meshes/folk_right.STL" />
      </geometry>
      <material
        name="">
        <color
          rgba="0.898039215686275 0.917647058823529 0.929411764705882 1" />
      </material>
    </visual>
    <collision>
      <origin
        xyz="0 0 0"
        rpy="0 0 0" />
      <geometry>
        <mesh
          filename="package://Holonomic/meshes/folk_right.STL" />
      </geometry>
    </collision>
  </link>
  <joint
    name="folk_right_fixed"
    type="fixed">
    <origin
      xyz="0 0.257035355339075 0"
      rpy="0 0 1.5707963267949" />
    <parent
      link="base_link" />
    <child
      link="folk_right" />
    <axis
      xyz="0 0 0" />
  </joint>
</robot>