<?xml version="1.0" encoding="utf-8"?>
<!-- This URDF was automatically created by SolidWorks to URDF Exporter! Originally created by Stephen Brawner (brawner@gmail.com) 
     Commit Version: 1.6.0-4-g7f85cfe  Build Version: 1.6.7995.38578
     For more information, please see http://wiki.ros.org/sw_urdf_exporter -->
<robot
  name="Holonomic">
  <link
    name="base_link">
    <inertial>
      <origin
        xyz="-1.61679833965422E-08 0.129901363247374 -0.00874403559770026"
        rpy="0 0 0" />
      <mass
        value="3.34064808867752" />
      <inertia
        ixx="0.0576995775576278"
        ixy="5.10236467379472E-19"
        ixz="-5.64437464605889E-14"
        iyy="0.0133526650283985"
        iyz="-4.88200838462323E-08"
        izz="0.0706132037943649" />
    </inertial>
    <visual>
      <origin
        xyz="0 0 0"
        rpy="0 0 0" />
      <geometry>
        <mesh
          filename="package://Holonomic/meshes/base_link.STL" />
      </geometry>
      <material
        name="">
        <color
          rgba="0.898039215686275 0.917647058823529 0.929411764705882 1" />
      </material>
    </visual>
    <collision>
      <origin
        xyz="0 0 0"
        rpy="0 0 0" />
      <geometry>
        <mesh
          filename="package://Holonomic/meshes/base_link.STL" />
      </geometry>
    </collision>
  </link>
  <link
    name="wheel_fr_right">
    <inertial>
      <origin
        xyz="5.55111512312578E-17 2.77555756156289E-16 -0.0264473304136225"
        rpy="0 0 0" />
      <mass
        value="0.321375664058356" />
      <inertia
        ixx="9.13370307716635E-05"
        ixy="-1.67873124224534E-18"
        ixz="4.70800380740584E-18"
        iyy="9.13370307716673E-05"
        iyz="7.85632888152758E-17"
        izz="0.000112444996454029" />
    </inertial>
    <visual>
      <origin
        xyz="0 0 0"
        rpy="0 0 0" />
      <geometry>
        <mesh
          filename="package://Holonomic/meshes/wheel_fr_right.STL" />
      </geometry>
      <material
        name="">
        <color
          rgba="0.776470588235294 0.756862745098039 0.737254901960784 1" />
      </material>
    </visual>
    <collision>
      <origin
        xyz="0 0 0"
        rpy="0 0 0" />
      <geometry>
        <mesh
          filename="package://Holonomic/meshes/wheel_fr_right.STL" />
      </geometry>
    </collision>
  </link>
  <joint
    name="joint_fr_right"
    type="continuous">
    <origin
      xyz="0.195390712673452 0.172500000000024 -0.0850000000000468"
      rpy="1.5707963267949 0 1.5707963267949" />
    <parent
      link="base_link" />
    <child
      link="wheel_fr_right" />
    <axis
      xyz="0 0 -1" />
  </joint>
  <link
    name="wheel_bk_right">
    <inertial>
      <origin
        xyz="-6.66133814775094E-16 -4.44089209850063E-16 -0.0264473304136225"
        rpy="0 0 0" />
      <mass
        value="0.321375664058355" />
      <inertia
        ixx="9.1337030771674E-05"
        ixy="-4.81313624316035E-19"
        ixz="-1.04925563926271E-18"
        iyy="9.13370307716748E-05"
        iyz="-7.76324467943278E-17"
        izz="0.00011244499645404" />
    </inertial>
    <visual>
      <origin
        xyz="0 0 0"
        rpy="0 0 0" />
      <geometry>
        <mesh
          filename="package://Holonomic/meshes/wheel_bk_right.STL" />
      </geometry>
      <material
        name="">
        <color
          rgba="0.776470588235294 0.756862745098039 0.737254901960784 1" />
      </material>
    </visual>
    <collision>
      <origin
        xyz="0 0 0"
        rpy="0 0 0" />
      <geometry>
        <mesh
          filename="package://Holonomic/meshes/wheel_bk_right.STL" />
      </geometry>
    </collision>
  </link>
  <joint
    name="joint_bk_right"
    type="continuous">
    <origin
      xyz="0.195390712673452 -0.192499999999931 -0.0850000000000466"
      rpy="-1.5707963267949 0 -1.5707963267949" />
    <parent
      link="base_link" />
    <child
      link="wheel_bk_right" />
    <axis
      xyz="0 0 -1" />
  </joint>
  <link
    name="wheel_fr_left">
    <inertial>
      <origin
        xyz="-3.60822483003176E-16 -6.10622663543836E-16 -0.0264433822598784"
        rpy="0 0 0" />
      <mass
        value="0.321375664058358" />
      <inertia
        ixx="9.13370307716814E-05"
        ixy="-7.15960453555618E-19"
        ixz="2.65291344955407E-19"
        iyy="9.13370307716819E-05"
        iyz="-7.43046201007476E-17"
        izz="0.000112444996454048" />
    </inertial>
    <visual>
      <origin
        xyz="0 0 0"
        rpy="0 0 0" />
      <geometry>
        <mesh
          filename="package://Holonomic/meshes/wheel_fr_left.STL" />
      </geometry>
      <material
        name="">
        <color
          rgba="0.776470588235294 0.756862745098039 0.737254901960784 1" />
      </material>
    </visual>
    <collision>
      <origin
        xyz="0 0 0"
        rpy="0 0 0" />
      <geometry>
        <mesh
          filename="package://Holonomic/meshes/wheel_fr_left.STL" />
      </geometry>
    </collision>
  </link>
  <joint
    name="joint_fr_left"
    type="continuous">
    <origin
      xyz="-0.195390712673501 0.172500000000024 -0.085000000000046"
      rpy="1.5707963267949 0 -1.5707963267949" />
    <parent
      link="base_link" />
    <child
      link="wheel_fr_left" />
    <axis
      xyz="0 0 1" />
  </joint>
  <link
    name="wheel_bk_left">
    <inertial>
      <origin
        xyz="-3.33066907387547E-16 -2.77555756156289E-16 -0.0264433822598769"
        rpy="0 0 0" />
      <mass
        value="0.321375664058358" />
      <inertia
        ixx="9.13370307716939E-05"
        ixy="9.27531473725865E-19"
        ixz="-4.22642793993102E-18"
        iyy="9.13370307716905E-05"
        iyz="-7.50389680426287E-17"
        izz="0.00011244499645406" />
    </inertial>
    <visual>
      <origin
        xyz="0 0 0"
        rpy="0 0 0" />
      <geometry>
        <mesh
          filename="package://Holonomic/meshes/wheel_bk_left.STL" />
      </geometry>
      <material
        name="">
        <color
          rgba="0.776470588235294 0.756862745098039 0.737254901960784 1" />
      </material>
    </visual>
    <collision>
      <origin
        xyz="0 0 0"
        rpy="0 0 0" />
      <geometry>
        <mesh
          filename="package://Holonomic/meshes/wheel_bk_left.STL" />
      </geometry>
    </collision>
  </link>
  <joint
    name="joint_bk_left"
    type="continuous">
    <origin
      xyz="-0.195390712673501 -0.192499999999931 -0.085000000000046"
      rpy="1.5707963267949 0 -1.5707963267949" />
    <parent
      link="base_link" />
    <child
      link="wheel_bk_left" />
    <axis
      xyz="0 0 1" />
  </joint>
</robot>