<sdf version='1.7'>
  <world name='default'>
    <light name='sun' type='directional'>
      <cast_shadows>1</cast_shadows>
      <pose>0 0 10 0 -0 0</pose>
      <diffuse>0.8 0.8 0.8 1</diffuse>
      <specular>0.2 0.2 0.2 1</specular>
      <attenuation>
        <range>1000</range>
        <constant>0.9</constant>
        <linear>0.01</linear>
        <quadratic>0.001</quadratic>
      </attenuation>
      <direction>-0.5 0.1 -0.9</direction>
      <spot>
        <inner_angle>0</inner_angle>
        <outer_angle>0</outer_angle>
        <falloff>0</falloff>
      </spot>
    </light>
    <model name='ground_plane'>
      <static>1</static>
      <link name='link'>
        <collision name='collision'>
          <geometry>
            <plane>
              <normal>0 0 1</normal>
              <size>100 100</size>
            </plane>
          </geometry>
          <surface>
            <friction>
              <ode>
                <mu>100</mu>
                <mu2>50</mu2>
              </ode>
              <torsional>
                <ode/>
              </torsional>
            </friction>
            <contact>
              <ode/>
            </contact>
            <bounce/>
          </surface>
          <max_contacts>10</max_contacts>
        </collision>
        <visual name='visual'>
          <cast_shadows>0</cast_shadows>
          <geometry>
            <plane>
              <normal>0 0 1</normal>
              <size>100 100</size>
            </plane>
          </geometry>
          <material>
            <script>
              <uri>file://media/materials/scripts/gazebo.material</uri>
              <name>Gazebo/Grey</name>
            </script>
          </material>
        </visual>
        <self_collide>0</self_collide>
        <enable_wind>0</enable_wind>
        <kinematic>0</kinematic>
      </link>
    </model>
    <gravity>0 0 -9.8</gravity>
    <magnetic_field>6e-06 2.3e-05 -4.2e-05</magnetic_field>
    <atmosphere type='adiabatic'/>
    <physics type='ode'>
      <max_step_size>0.001</max_step_size>
      <real_time_factor>1</real_time_factor>
      <real_time_update_rate>1000</real_time_update_rate>
    </physics>
    <scene>
      <ambient>0.4 0.4 0.4 1</ambient>
      <background>0.7 0.7 0.7 1</background>
      <shadows>1</shadows>
    </scene>
    <audio>
      <device>default</device>
    </audio>
    <wind/>
    <spherical_coordinates>
      <surface_model>EARTH_WGS84</surface_model>
      <latitude_deg>0</latitude_deg>
      <longitude_deg>0</longitude_deg>
      <elevation>0</elevation>
      <heading_deg>0</heading_deg>
    </spherical_coordinates>
    <model name='car'>
      <link name='base_footprint'>
        <inertial>
          <pose>0.25 0 0.02 0 -0 0</pose>
          <mass>7.6</mass>
          <inertia>
            <ixx>0.103613</ixx>
            <ixy>0</ixy>
            <ixz>-2.08167e-17</ixz>
            <iyy>0.160613</iyy>
            <iyz>0</iyz>
            <izz>0.160613</izz>
          </inertia>
        </inertial>
        <collision name='base_footprint_fixed_joint_lump__chassis_link_collision'>
          <pose>0.25 0 0.02 0 -0 0</pose>
          <geometry>
            <box>
              <size>0.5 0.4 0.06</size>
            </box>
          </geometry>
          <max_contacts>10</max_contacts>
          <surface>
            <contact>
              <ode/>
            </contact>
            <bounce/>
            <friction>
              <torsional>
                <ode/>
              </torsional>
              <ode/>
            </friction>
          </surface>
        </collision>
        <visual name='base_footprint_fixed_joint_lump__chassis_link_visual'>
          <pose>0.25 0 0.02 0 -0 0</pose>
          <geometry>
            <box>
              <size>0.5 0.4 0.06</size>
            </box>
          </geometry>
        </visual>
        <velocity_decay>
          <linear>7e-05</linear>
          <angular>7e-05</angular>
        </velocity_decay>
        <self_collide>0</self_collide>
        <enable_wind>0</enable_wind>
        <kinematic>0</kinematic>
      </link>
      <joint name='back_left_shock_joint' type='prismatic'>
        <pose relative_to='base_footprint'>0 0.2 -0.045 0 -0 0</pose>
        <parent>base_footprint</parent>
        <child>back_left_wheel_shock</child>
        <axis>
          <xyz>0 0 1</xyz>
          <limit>
            <lower>0</lower>
            <upper>0.09</upper>
            <effort>100</effort>
            <velocity>100</velocity>
          </limit>
          <dynamics>
            <spring_reference>0</spring_reference>
            <spring_stiffness>0</spring_stiffness>
          </dynamics>
        </axis>
      </joint>
      <link name='back_left_wheel_shock'>
        <pose relative_to='back_left_shock_joint'>0 0 0 0 -0 0</pose>
        <inertial>
          <pose>0 0 0 0 -0 0</pose>
          <mass>0.01</mass>
          <inertia>
            <ixx>0.015</ixx>
            <ixy>0</ixy>
            <ixz>0</ixz>
            <iyy>0.0375</iyy>
            <iyz>0</iyz>
            <izz>0.0375</izz>
          </inertia>
        </inertial>
        <collision name='back_left_wheel_shock_collision'>
          <pose>0 0 0.1 0 -0 0</pose>
          <geometry>
            <cylinder>
              <length>0.05</length>
              <radius>0.01</radius>
            </cylinder>
          </geometry>
          <max_contacts>10</max_contacts>
          <surface>
            <contact>
              <ode/>
            </contact>
            <bounce/>
            <friction>
              <torsional>
                <ode/>
              </torsional>
              <ode/>
            </friction>
          </surface>
        </collision>
        <visual name='back_left_wheel_shock_visual'>
          <pose>0 0 0.1 0 -0 0</pose>
          <geometry>
            <cylinder>
              <length>0.05</length>
              <radius>0.01</radius>
            </cylinder>
          </geometry>
        </visual>
        <self_collide>0</self_collide>
        <enable_wind>0</enable_wind>
        <kinematic>0</kinematic>
      </link>
      <joint name='back_left_wheel_joint' type='revolute'>
        <pose relative_to='back_left_wheel_shock'>0 0 0 -1.5708 0 0</pose>
        <parent>back_left_wheel_shock</parent>
        <child>back_left_wheel</child>
        <axis>
          <xyz>0 0 1</xyz>
          <limit>
            <effort>10000</effort>
            <velocity>500</velocity>
            <lower>-1e+16</lower>
            <upper>1e+16</upper>
          </limit>
          <dynamics>
            <spring_reference>0</spring_reference>
            <spring_stiffness>0</spring_stiffness>
          </dynamics>
        </axis>
      </joint>
      <link name='back_left_wheel'>
        <pose relative_to='back_left_wheel_joint'>0 0 0 0 -0 0</pose>
        <inertial>
          <pose>0 0 0 0 -0 0</pose>
          <mass>0.1</mass>
          <inertia>
            <ixx>0.000108408</ixx>
            <ixy>0</ixy>
            <ixz>0</ixz>
            <iyy>0.000108408</iyy>
            <iyz>0</iyz>
            <izz>0.00018</izz>
          </inertia>
        </inertial>
        <collision name='back_left_wheel_collision'>
          <pose>0 0 0 0 -0 0</pose>
          <geometry>
            <cylinder>
              <length>0.047</length>
              <radius>0.06</radius>
            </cylinder>
          </geometry>
          <surface>
            <contact>
              <ode/>
            </contact>
            <friction>
              <ode>
                <mu>2</mu>
              </ode>
              <torsional>
                <ode/>
              </torsional>
            </friction>
            <bounce/>
          </surface>
          <max_contacts>10</max_contacts>
        </collision>
        <visual name='back_left_wheel_visual'>
          <pose>0 0 0 0 -0 0</pose>
          <geometry>
            <cylinder>
              <length>0.047</length>
              <radius>0.06</radius>
            </cylinder>
          </geometry>
          <material>
            <script>
              <name>Gazebo/DarkGrey</name>
              <uri>file://media/materials/scripts/gazebo.material</uri>
            </script>
          </material>
        </visual>
        <self_collide>0</self_collide>
        <enable_wind>0</enable_wind>
        <kinematic>0</kinematic>
      </link>
      <joint name='back_right_shock_joint' type='prismatic'>
        <pose relative_to='base_footprint'>0 -0.2 -0.045 0 -0 0</pose>
        <parent>base_footprint</parent>
        <child>back_right_wheel_shock</child>
        <axis>
          <xyz>0 0 1</xyz>
          <limit>
            <lower>0</lower>
            <upper>0.09</upper>
            <effort>100</effort>
            <velocity>100</velocity>
          </limit>
          <dynamics>
            <spring_reference>0</spring_reference>
            <spring_stiffness>0</spring_stiffness>
          </dynamics>
        </axis>
      </joint>
      <link name='back_right_wheel_shock'>
        <pose relative_to='back_right_shock_joint'>0 0 0 0 -0 0</pose>
        <inertial>
          <pose>0 0 0 0 -0 0</pose>
          <mass>0.01</mass>
          <inertia>
            <ixx>0.015</ixx>
            <ixy>0</ixy>
            <ixz>0</ixz>
            <iyy>0.0375</iyy>
            <iyz>0</iyz>
            <izz>0.0375</izz>
          </inertia>
        </inertial>
        <collision name='back_right_wheel_shock_collision'>
          <pose>0 0 0.1 0 -0 0</pose>
          <geometry>
            <cylinder>
              <length>0.05</length>
              <radius>0.01</radius>
            </cylinder>
          </geometry>
          <max_contacts>10</max_contacts>
          <surface>
            <contact>
              <ode/>
            </contact>
            <bounce/>
            <friction>
              <torsional>
                <ode/>
              </torsional>
              <ode/>
            </friction>
          </surface>
        </collision>
        <visual name='back_right_wheel_shock_visual'>
          <pose>0 0 0.1 0 -0 0</pose>
          <geometry>
            <cylinder>
              <length>0.05</length>
              <radius>0.01</radius>
            </cylinder>
          </geometry>
        </visual>
        <self_collide>0</self_collide>
        <enable_wind>0</enable_wind>
        <kinematic>0</kinematic>
      </link>
      <joint name='back_right_wheel_joint' type='revolute'>
        <pose relative_to='back_right_wheel_shock'>0 0 0 -1.5708 0 0</pose>
        <parent>back_right_wheel_shock</parent>
        <child>back_right_wheel</child>
        <axis>
          <xyz>0 0 1</xyz>
          <limit>
            <effort>10000</effort>
            <velocity>500</velocity>
            <lower>-1e+16</lower>
            <upper>1e+16</upper>
          </limit>
          <dynamics>
            <spring_reference>0</spring_reference>
            <spring_stiffness>0</spring_stiffness>
          </dynamics>
        </axis>
      </joint>
      <link name='back_right_wheel'>
        <pose relative_to='back_right_wheel_joint'>0 0 0 0 -0 0</pose>
        <inertial>
          <pose>0 0 0 0 -0 0</pose>
          <mass>0.1</mass>
          <inertia>
            <ixx>0.000108408</ixx>
            <ixy>0</ixy>
            <ixz>0</ixz>
            <iyy>0.000108408</iyy>
            <iyz>0</iyz>
            <izz>0.00018</izz>
          </inertia>
        </inertial>
        <collision name='back_right_wheel_collision'>
          <pose>0 0 0 0 -0 0</pose>
          <geometry>
            <cylinder>
              <length>0.047</length>
              <radius>0.06</radius>
            </cylinder>
          </geometry>
          <surface>
            <contact>
              <ode/>
            </contact>
            <friction>
              <ode>
                <mu>2</mu>
              </ode>
              <torsional>
                <ode/>
              </torsional>
            </friction>
            <bounce/>
          </surface>
          <max_contacts>10</max_contacts>
        </collision>
        <visual name='back_right_wheel_visual'>
          <pose>0 0 0 0 -0 0</pose>
          <geometry>
            <cylinder>
              <length>0.047</length>
              <radius>0.06</radius>
            </cylinder>
          </geometry>
          <material>
            <script>
              <name>Gazebo/DarkGrey</name>
              <uri>file://media/materials/scripts/gazebo.material</uri>
            </script>
          </material>
        </visual>
        <self_collide>0</self_collide>
        <enable_wind>0</enable_wind>
        <kinematic>0</kinematic>
      </link>
      <joint name='front_left_shock_joint' type='prismatic'>
        <pose relative_to='base_footprint'>0.5 0.2 -0.045 0 -0 0</pose>
        <parent>base_footprint</parent>
        <child>front_left_wheel_shock</child>
        <axis>
          <xyz>0 0 1</xyz>
          <limit>
            <lower>0</lower>
            <upper>0.09</upper>
            <effort>100</effort>
            <velocity>100</velocity>
          </limit>
          <dynamics>
            <spring_reference>0</spring_reference>
            <spring_stiffness>0</spring_stiffness>
          </dynamics>
        </axis>
      </joint>
      <link name='front_left_wheel_shock'>
        <pose relative_to='front_left_shock_joint'>0 0 0 0 -0 0</pose>
        <inertial>
          <pose>0 0 0 0 -0 0</pose>
          <mass>0.01</mass>
          <inertia>
            <ixx>0.015</ixx>
            <ixy>0</ixy>
            <ixz>0</ixz>
            <iyy>0.0375</iyy>
            <iyz>0</iyz>
            <izz>0.0375</izz>
          </inertia>
        </inertial>
        <collision name='front_left_wheel_shock_collision'>
          <pose>0 0 0.1 0 -0 0</pose>
          <geometry>
            <cylinder>
              <length>0.05</length>
              <radius>0.01</radius>
            </cylinder>
          </geometry>
          <max_contacts>10</max_contacts>
          <surface>
            <contact>
              <ode/>
            </contact>
            <bounce/>
            <friction>
              <torsional>
                <ode/>
              </torsional>
              <ode/>
            </friction>
          </surface>
        </collision>
        <visual name='front_left_wheel_shock_visual'>
          <pose>0 0 0.1 0 -0 0</pose>
          <geometry>
            <cylinder>
              <length>0.05</length>
              <radius>0.01</radius>
            </cylinder>
          </geometry>
        </visual>
        <self_collide>0</self_collide>
        <enable_wind>0</enable_wind>
        <kinematic>0</kinematic>
      </link>
      <joint name='front_left_wheel_steer_joint' type='revolute'>
        <pose relative_to='front_left_wheel_shock'>0 0 0 0 -0 0</pose>
        <parent>front_left_wheel_shock</parent>
        <child>front_left_wheel_steer</child>
        <axis>
          <xyz>0 0 1</xyz>
          <limit>
            <lower>-1</lower>
            <upper>1</upper>
            <effort>1</effort>
            <velocity>5</velocity>
          </limit>
          <dynamics>
            <spring_reference>0</spring_reference>
            <spring_stiffness>0</spring_stiffness>
          </dynamics>
        </axis>
      </joint>
      <link name='front_left_wheel_steer'>
        <pose relative_to='front_left_wheel_steer_joint'>0 0 0 0 -0 0</pose>
        <inertial>
          <pose>0 0 0 0 -0 0</pose>
          <mass>0.1</mass>
          <inertia>
            <ixx>5.1458e-05</ixx>
            <ixy>0</ixy>
            <ixz>0</ixz>
            <iyy>5.1458e-05</iyy>
            <iyz>0</iyz>
            <izz>6.125e-05</izz>
          </inertia>
        </inertial>
        <collision name='front_left_wheel_steer_collision'>
          <pose>0 0 0 0 -0 0</pose>
          <geometry>
            <cylinder>
              <length>0.01</length>
              <radius>0.01</radius>
            </cylinder>
          </geometry>
          <max_contacts>10</max_contacts>
          <surface>
            <contact>
              <ode/>
            </contact>
            <bounce/>
            <friction>
              <torsional>
                <ode/>
              </torsional>
              <ode/>
            </friction>
          </surface>
        </collision>
        <visual name='front_left_wheel_steer_visual'>
          <pose>0 0 0 0 -0 0</pose>
          <geometry>
            <cylinder>
              <length>0.01</length>
              <radius>0.01</radius>
            </cylinder>
          </geometry>
        </visual>
        <self_collide>0</self_collide>
        <enable_wind>0</enable_wind>
        <kinematic>0</kinematic>
      </link>
      <joint name='front_left_wheel_joint' type='revolute'>
        <pose relative_to='front_left_wheel_steer'>0 0 0 -1.5708 0 0</pose>
        <parent>front_left_wheel_steer</parent>
        <child>front_left_wheel</child>
        <axis>
          <xyz>0 0 1</xyz>
          <limit>
            <lower>-1e+16</lower>
            <upper>1e+16</upper>
          </limit>
          <dynamics>
            <spring_reference>0</spring_reference>
            <spring_stiffness>0</spring_stiffness>
          </dynamics>
        </axis>
      </joint>
      <link name='front_left_wheel'>
        <pose relative_to='front_left_wheel_joint'>0 0 0 0 -0 0</pose>
        <inertial>
          <pose>0 0 0 0 -0 0</pose>
          <mass>0.1</mass>
          <inertia>
            <ixx>0.000108408</ixx>
            <ixy>0</ixy>
            <ixz>0</ixz>
            <iyy>0.000108408</iyy>
            <iyz>0</iyz>
            <izz>0.00018</izz>
          </inertia>
        </inertial>
        <collision name='front_left_wheel_collision'>
          <pose>0 0 0 0 -0 0</pose>
          <geometry>
            <cylinder>
              <length>0.047</length>
              <radius>0.06</radius>
            </cylinder>
          </geometry>
          <surface>
            <contact>
              <ode/>
            </contact>
            <friction>
              <ode>
                <mu>2</mu>
              </ode>
              <torsional>
                <ode/>
              </torsional>
            </friction>
            <bounce/>
          </surface>
          <max_contacts>10</max_contacts>
        </collision>
        <visual name='front_left_wheel_visual'>
          <pose>0 0 0 0 -0 0</pose>
          <geometry>
            <cylinder>
              <length>0.047</length>
              <radius>0.06</radius>
            </cylinder>
          </geometry>
          <material>
            <script>
              <name>Gazebo/DarkGrey</name>
              <uri>file://media/materials/scripts/gazebo.material</uri>
            </script>
          </material>
        </visual>
        <self_collide>0</self_collide>
        <enable_wind>0</enable_wind>
        <kinematic>0</kinematic>
      </link>
      <joint name='front_right_shock_joint' type='prismatic'>
        <pose relative_to='base_footprint'>0.5 -0.2 -0.045 0 -0 0</pose>
        <parent>base_footprint</parent>
        <child>front_right_wheel_shock</child>
        <axis>
          <xyz>0 0 1</xyz>
          <limit>
            <lower>0</lower>
            <upper>0.09</upper>
            <effort>100</effort>
            <velocity>100</velocity>
          </limit>
          <dynamics>
            <spring_reference>0</spring_reference>
            <spring_stiffness>0</spring_stiffness>
          </dynamics>
        </axis>
      </joint>
      <link name='front_right_wheel_shock'>
        <pose relative_to='front_right_shock_joint'>0 0 0 0 -0 0</pose>
        <inertial>
          <pose>0 0 0 0 -0 0</pose>
          <mass>0.01</mass>
          <inertia>
            <ixx>0.015</ixx>
            <ixy>0</ixy>
            <ixz>0</ixz>
            <iyy>0.0375</iyy>
            <iyz>0</iyz>
            <izz>0.0375</izz>
          </inertia>
        </inertial>
        <collision name='front_right_wheel_shock_collision'>
          <pose>0 0 0.1 0 -0 0</pose>
          <geometry>
            <cylinder>
              <length>0.05</length>
              <radius>0.01</radius>
            </cylinder>
          </geometry>
          <max_contacts>10</max_contacts>
          <surface>
            <contact>
              <ode/>
            </contact>
            <bounce/>
            <friction>
              <torsional>
                <ode/>
              </torsional>
              <ode/>
            </friction>
          </surface>
        </collision>
        <visual name='front_right_wheel_shock_visual'>
          <pose>0 0 0.1 0 -0 0</pose>
          <geometry>
            <cylinder>
              <length>0.05</length>
              <radius>0.01</radius>
            </cylinder>
          </geometry>
        </visual>
        <self_collide>0</self_collide>
        <enable_wind>0</enable_wind>
        <kinematic>0</kinematic>
      </link>
      <joint name='front_right_wheel_steer_joint' type='revolute'>
        <pose relative_to='front_right_wheel_shock'>0 0 0 0 -0 0</pose>
        <parent>front_right_wheel_shock</parent>
        <child>front_right_wheel_steer</child>
        <axis>
          <xyz>0 0 1</xyz>
          <limit>
            <lower>-1</lower>
            <upper>1</upper>
            <effort>1</effort>
            <velocity>5</velocity>
          </limit>
          <dynamics>
            <spring_reference>0</spring_reference>
            <spring_stiffness>0</spring_stiffness>
          </dynamics>
        </axis>
      </joint>
      <link name='front_right_wheel_steer'>
        <pose relative_to='front_right_wheel_steer_joint'>0 0 0 0 -0 0</pose>
        <inertial>
          <pose>0 0 0 0 -0 0</pose>
          <mass>0.1</mass>
          <inertia>
            <ixx>5.1458e-05</ixx>
            <ixy>0</ixy>
            <ixz>0</ixz>
            <iyy>5.1458e-05</iyy>
            <iyz>0</iyz>
            <izz>6.125e-05</izz>
          </inertia>
        </inertial>
        <collision name='front_right_wheel_steer_collision'>
          <pose>0 0 0 0 -0 0</pose>
          <geometry>
            <cylinder>
              <length>0.01</length>
              <radius>0.01</radius>
            </cylinder>
          </geometry>
          <max_contacts>10</max_contacts>
          <surface>
            <contact>
              <ode/>
            </contact>
            <bounce/>
            <friction>
              <torsional>
                <ode/>
              </torsional>
              <ode/>
            </friction>
          </surface>
        </collision>
        <visual name='front_right_wheel_steer_visual'>
          <pose>0 0 0 0 -0 0</pose>
          <geometry>
            <cylinder>
              <length>0.01</length>
              <radius>0.01</radius>
            </cylinder>
          </geometry>
        </visual>
        <self_collide>0</self_collide>
        <enable_wind>0</enable_wind>
        <kinematic>0</kinematic>
      </link>
      <joint name='front_right_wheel_joint' type='revolute'>
        <pose relative_to='front_right_wheel_steer'>0 0 0 -1.5708 0 0</pose>
        <parent>front_right_wheel_steer</parent>
        <child>front_right_wheel</child>
        <axis>
          <xyz>0 0 1</xyz>
          <limit>
            <lower>-1e+16</lower>
            <upper>1e+16</upper>
          </limit>
          <dynamics>
            <spring_reference>0</spring_reference>
            <spring_stiffness>0</spring_stiffness>
          </dynamics>
        </axis>
      </joint>
      <link name='front_right_wheel'>
        <pose relative_to='front_right_wheel_joint'>0 0 0 0 -0 0</pose>
        <inertial>
          <pose>0 0 0 0 -0 0</pose>
          <mass>0.1</mass>
          <inertia>
            <ixx>0.000108408</ixx>
            <ixy>0</ixy>
            <ixz>0</ixz>
            <iyy>0.000108408</iyy>
            <iyz>0</iyz>
            <izz>0.00018</izz>
          </inertia>
        </inertial>
        <collision name='front_right_wheel_collision'>
          <pose>0 0 0 0 -0 0</pose>
          <geometry>
            <cylinder>
              <length>0.047</length>
              <radius>0.06</radius>
            </cylinder>
          </geometry>
          <surface>
            <contact>
              <ode/>
            </contact>
            <friction>
              <ode>
                <mu>2</mu>
              </ode>
              <torsional>
                <ode/>
              </torsional>
            </friction>
            <bounce/>
          </surface>
          <max_contacts>10</max_contacts>
        </collision>
        <visual name='front_right_wheel_visual'>
          <pose>0 0 0 0 -0 0</pose>
          <geometry>
            <cylinder>
              <length>0.047</length>
              <radius>0.06</radius>
            </cylinder>
          </geometry>
          <material>
            <script>
              <name>Gazebo/DarkGrey</name>
              <uri>file://media/materials/scripts/gazebo.material</uri>
            </script>
          </material>
        </visual>
        <self_collide>0</self_collide>
        <enable_wind>0</enable_wind>
        <kinematic>0</kinematic>
      </link>
      <static>0</static>
      <plugin name='car_gazebo_plugin' filename='libcar_gazebo_plugin.so'/>
      <pose>0 0 0 0 -0 0</pose>
    </model>
    <state world_name='default'>
      <sim_time>47 206000000</sim_time>
      <real_time>47 468688772</real_time>
      <wall_time>1699936131 32564980</wall_time>
      <iterations>47206</iterations>
      <model name='car'>
        <pose>1.16957 0.0394 0.067744 5.5e-05 1.5e-05 0.017836</pose>
        <scale>1 1 1</scale>
        <link name='back_left_wheel'>
          <pose>1.166 0.239368 0.06 -1.57078 1.52082 0.017851</pose>
          <velocity>-0.000655 -0.000371 -7e-06 0.006224 -0.011779 0.002192</velocity>
          <acceleration>-0.643616 -0.246634 -0.075329 -2.33372 -0.689807 -2.48122</acceleration>
          <wrench>-0.064362 -0.024663 -0.007533 0 -0 0</wrench>
        </link>
        <link name='back_left_wheel_shock'>
          <pose>1.166 0.239368 0.06 5.5e-05 1.5e-05 0.017836</pose>
          <velocity>-0.000656 -0.00038 -7e-06 -0.004534 -0.001539 0.001774</velocity>
          <acceleration>-0.644584 -0.270226 -0.075183 1.61553 -1.27215 -0.703717</acceleration>
          <wrench>-0.006446 -0.002702 -0.000752 0 -0 0</wrench>
        </link>
        <link name='back_right_wheel'>
          <pose>1.17314 -0.160568 0.06 1.57076 1.52098 -3.1238</pose>
          <velocity>6.1e-05 -0.000194 3.4e-05 0.003238 0.001047 0.000505</velocity>
          <acceleration>0.330571 -0.384919 -0.150816 -2.972 -0.250129 -1.98624</acceleration>
          <wrench>0.033057 -0.038492 -0.015082 0 -0 0</wrench>
        </link>
        <link name='back_right_wheel_shock'>
          <pose>1.17314 -0.160568 0.06 5.5e-05 1.5e-05 0.017836</pose>
          <velocity>6.1e-05 -0.00017 3.4e-05 -0.004566 -0.00154 0.001769</velocity>
          <acceleration>0.327551 -0.374249 -0.150657 -1.40659 0.788055 2.43966</acceleration>
          <wrench>0.003276 -0.003742 -0.001507 0 -0 0</wrench>
        </link>
        <link name='base_footprint'>
          <pose>1.16957 0.0394 0.067744 5.5e-05 1.5e-05 0.017836</pose>
          <velocity>-0.000309 -0.000457 0.00032 -0.004599 -0.001541 0.001779</velocity>
          <acceleration>-0.178261 0.079312 -0.014004 0.18188 -0.522477 2.44594</acceleration>
          <wrench>-1.35478 0.602774 -0.106431 0 -0 0</wrench>
        </link>
        <link name='front_left_wheel'>
          <pose>1.66592 0.248286 0.06 1.5708 0.383089 -2.49431</pose>
          <velocity>-0.000436 5.4e-05 0.000153 -0.001056 -0.006912 0.000988</velocity>
          <acceleration>-0.326146 0.153067 0.067714 -0.144439 1.16613 -1.45216</acceleration>
          <wrench>-0.032615 0.015307 0.006771 0 -0 0</wrench>
        </link>
        <link name='front_left_wheel_shock'>
          <pose>1.66592 0.248286 0.06 5.5e-05 1.5e-05 0.017836</pose>
          <velocity>-0.000486 0.000113 0.000152 -0.004604 -0.001538 0.001772</velocity>
          <acceleration>-0.379731 0.201171 0.065745 -1.35007 -1.30998 -0.7105</acceleration>
          <wrench>-0.003797 0.002012 0.000657 0 -0 0</wrench>
        </link>
        <link name='front_left_wheel_steer'>
          <pose>1.66592 0.248286 0.06 1.2e-05 -2e-05 0.647277</pose>
          <velocity>-0.000516 0.000162 0.000153 -0.001226 0.001014 0.001005</velocity>
          <acceleration>-0.428123 0.29352 0.066478 1.31379 0.335625 1.10505</acceleration>
          <wrench>-0.042812 0.029352 0.006648 0 -0 0</wrench>
        </link>
        <link name='front_right_wheel'>
          <pose>1.67306 -0.151651 0.06 1.5708 0.585539 2.6245</pose>
          <velocity>1.7e-05 0.000322 2.6e-05 -0.005362 0.000288 2e-05</velocity>
          <acceleration>0.255296 0.563265 -0.003056 0.274921 -1.54056 2.37847</acceleration>
          <wrench>0.02553 0.056326 -0.000306 0 -0 0</wrench>
        </link>
        <link name='front_right_wheel_shock'>
          <pose>1.67306 -0.15165 0.06 5.5e-05 1.5e-05 0.017836</pose>
          <velocity>5.2e-05 0.00043 2.7e-05 -0.004611 -0.001541 0.001784</velocity>
          <acceleration>0.328761 0.742319 -0.000806 1.86123 0.818357 2.45099</acceleration>
          <wrench>0.003288 0.007423 -8e-06 0 -0 0</wrench>
        </link>
        <link name='front_right_wheel_steer'>
          <pose>1.67306 -0.151651 0.06 4.8e-05 4.1e-05 -0.5171</pose>
          <velocity>2.7e-05 0.000348 2.7e-05 -0.004325 -0.001711 9.1e-05</velocity>
          <acceleration>0.287594 0.631195 -0.000379 -0.954086 -1.47236 2.73065</acceleration>
          <wrench>0.028759 0.06312 -3.8e-05 0 -0 0</wrench>
        </link>
      </model>
      <model name='ground_plane'>
        <pose>0 0 0 0 -0 0</pose>
        <scale>1 1 1</scale>
        <link name='link'>
          <pose>0 0 0 0 -0 0</pose>
          <velocity>0 0 0 0 -0 0</velocity>
          <acceleration>0 0 0 0 -0 0</acceleration>
          <wrench>0 0 0 0 -0 0</wrench>
        </link>
      </model>
      <light name='sun'>
        <pose>0 0 10 0 -0 0</pose>
      </light>
    </state>
    <gui fullscreen='0'>
      <camera name='user_camera'>
        <pose>-3.16347 -2.46734 2.92561 0 0.635643 0.960197</pose>
        <view_controller>orbit</view_controller>
        <projection_type>perspective</projection_type>
      </camera>
    </gui>
  </world>
</sdf>
