<?xml version="1.0" encoding="utf-8"?>
<!-- This URDF was automatically created by SolidWorks to URDF Exporter! Originally created by Stephen Brawner (brawner@gmail.com) 
     Commit Version: 1.6.0-4-g7f85cfe  Build Version: 1.6.7995.38578
     For more information, please see http://wiki.ros.org/sw_urdf_exporter -->
<robot
  name="Macanum">
  <link
    name="base_link">
    <inertial>
      <origin
        xyz="-1.12180791878025E-08 -0.00977485494714381 -0.017441883763565"
        rpy="0 0 0" />
      <mass
        value="2.29285820990711" />
      <inertia
        ixx="0.0312149550140326"
        ixy="5.63125731136887E-20"
        ixz="-5.5975853134656E-14"
        iyy="0.0132712718999651"
        iyz="-4.93932954500253E-08"
        izz="0.0441257339050913" />
    </inertial>
    <visual>
      <origin
        xyz="0 0 0"
        rpy="0 0 0" />
      <geometry>
        <mesh
          filename="package://Macanum/meshes/base_link.STL" />
      </geometry>
      <material
        name="">
        <color
          rgba="0.898039215686275 0.917647058823529 0.929411764705882 1" />
      </material>
    </visual>
    <collision>
      <origin
        xyz="0 0 0"
        rpy="0 0 0" />
      <geometry>
        <mesh
          filename="package://Macanum/meshes/base_link.STL" />
      </geometry>
    </collision>
  </link>
  <link
    name="wheel_fr_right">
    <inertial>
      <origin
        xyz="2.77555756156289E-16 3.33066907387547E-16 -0.0264473304136223"
        rpy="0 0 0" />
      <mass
        value="0.321375664058358" />
      <inertia
        ixx="9.13370307716643E-05"
        ixy="-1.71192400821012E-18"
        ixz="4.25413976781619E-18"
        iyy="9.13370307716681E-05"
        iyz="7.83101193126719E-17"
        izz="0.00011244499645403" />
    </inertial>
    <visual>
      <origin
        xyz="0 0 0"
        rpy="0 0 0" />
      <geometry>
        <mesh
          filename="package://Macanum/meshes/wheel_fr_right.STL" />
      </geometry>
      <material
        name="">
        <color
          rgba="0.776470588235294 0.756862745098039 0.737254901960784 1" />
      </material>
    </visual>
    <collision>
      <origin
        xyz="0 0 0"
        rpy="0 0 0" />
      <geometry>
        <mesh
          filename="package://Macanum/meshes/wheel_fr_right.STL" />
      </geometry>
    </collision>
  </link>
  <joint
    name="joint_fr_right"
    type="continuous">
    <origin
      xyz="0.195390712673452 0.172500000000024 -0.0860000000000467"
      rpy="1.5707963267949 0 1.5707963267949" />
    <parent
      link="base_link" />
    <child
      link="wheel_fr_right" />
    <axis
      xyz="0 0 -1" />
  </joint>
  <link
    name="wheel_bk_right">
    <inertial>
      <origin
        xyz="-5.55111512312578E-16 -3.88578058618805E-16 -0.0264473304136225"
        rpy="0 0 0" />
      <mass
        value="0.321375664058357" />
      <inertia
        ixx="9.13370307716783E-05"
        ixy="2.71932182752178E-19"
        ixz="1.51527202256925E-19"
        iyy="9.13370307716787E-05"
        iyz="-7.65174275816083E-17"
        izz="0.000112444996454044" />
    </inertial>
    <visual>
      <origin
        xyz="0 0 0"
        rpy="0 0 0" />
      <geometry>
        <mesh
          filename="package://Macanum/meshes/wheel_bk_right.STL" />
      </geometry>
      <material
        name="">
        <color
          rgba="0.776470588235294 0.756862745098039 0.737254901960784 1" />
      </material>
    </visual>
    <collision>
      <origin
        xyz="0 0 0"
        rpy="0 0 0" />
      <geometry>
        <mesh
          filename="package://Macanum/meshes/wheel_bk_right.STL" />
      </geometry>
    </collision>
  </link>
  <joint
    name="joint_bk_right"
    type="continuous">
    <origin
      xyz="0.195390712673452 -0.192499999999931 -0.0860000000000467"
      rpy="-1.5707963267949 0 -1.5707963267949" />
    <parent
      link="base_link" />
    <child
      link="wheel_bk_right" />
    <axis
      xyz="0 0 -1" />
  </joint>
  <link
    name="wheel_fr_left">
    <inertial>
      <origin
        xyz="-4.44089209850063E-16 -5.55111512312578E-17 -0.0264433822598774"
        rpy="0 0 0" />
      <mass
        value="0.321375664058357" />
      <inertia
        ixx="9.13370307716802E-05"
        ixy="-6.44042547859264E-19"
        ixz="-3.07573743412683E-19"
        iyy="9.13370307716807E-05"
        iyz="-7.44170609262975E-17"
        izz="0.000112444996454046" />
    </inertial>
    <visual>
      <origin
        xyz="0 0 0"
        rpy="0 0 0" />
      <geometry>
        <mesh
          filename="package://Macanum/meshes/wheel_fr_left.STL" />
      </geometry>
      <material
        name="">
        <color
          rgba="0.776470588235294 0.756862745098039 0.737254901960784 1" />
      </material>
    </visual>
    <collision>
      <origin
        xyz="0 0 0"
        rpy="0 0 0" />
      <geometry>
        <mesh
          filename="package://Macanum/meshes/wheel_fr_left.STL" />
      </geometry>
    </collision>
  </link>
  <joint
    name="joint_fr_left"
    type="continuous">
    <origin
      xyz="-0.195390712673501 0.172500000000024 -0.086000000000046"
      rpy="1.5707963267949 0 -1.5707963267949" />
    <parent
      link="base_link" />
    <child
      link="wheel_fr_left" />
    <axis
      xyz="0 0 1" />
  </joint>
  <link
    name="wheel_bk_left">
    <inertial>
      <origin
        xyz="-5.55111512312578E-16 -5.55111512312578E-17 -0.026443382259877"
        rpy="0 0 0" />
      <mass
        value="0.321375664058359" />
      <inertia
        ixx="9.13370307716977E-05"
        ixy="1.26288933342171E-18"
        ixz="-5.44702945781267E-18"
        iyy="9.13370307716954E-05"
        iyz="-7.63071863069849E-17"
        izz="0.000112444996454065" />
    </inertial>
    <visual>
      <origin
        xyz="0 0 0"
        rpy="0 0 0" />
      <geometry>
        <mesh
          filename="package://Macanum/meshes/wheel_bk_left.STL" />
      </geometry>
      <material
        name="">
        <color
          rgba="0.776470588235294 0.756862745098039 0.737254901960784 1" />
      </material>
    </visual>
    <collision>
      <origin
        xyz="0 0 0"
        rpy="0 0 0" />
      <geometry>
        <mesh
          filename="package://Macanum/meshes/wheel_bk_left.STL" />
      </geometry>
    </collision>
  </link>
  <joint
    name="joint_bk_left"
    type="continuous">
    <origin
      xyz="-0.195390712673501 -0.192499999999931 -0.086000000000046"
      rpy="1.5707963267949 0 -1.5707963267949" />
    <parent
      link="base_link" />
    <child
      link="wheel_bk_left" />
    <axis
      xyz="0 0 1" />
  </joint>
  <link
    name="folk_left">
    <inertial>
      <origin
        xyz="2.02693118416455 1.38000039370852 0.275"
        rpy="0 0 0" />
      <mass
        value="0.524544939385207" />
      <inertia
        ixx="0.0132439651239293"
        ixy="-2.33949015367526E-16"
        ixz="-2.27031732307994E-19"
        iyy="0.0132439651530278"
        iyz="-4.954292307034E-18"
        izz="4.21229162907784E-05" />
    </inertial>
    <visual>
      <origin
        xyz="0 0 0"
        rpy="0 0 0" />
      <geometry>
        <mesh
          filename="package://Macanum/meshes/folk_left.STL" />
      </geometry>
      <material
        name="">
        <color
          rgba="0.898039215686275 0.917647058823529 0.929411764705882 1" />
      </material>
    </visual>
    <collision>
      <origin
        xyz="0 0 0"
        rpy="0 0 0" />
      <geometry>
        <mesh
          filename="package://Macanum/meshes/folk_left.STL" />
      </geometry>
    </collision>
  </link>
  <joint
    name="folk_left_fixed"
    type="fixed">
    <origin
      xyz="-2.09443121112492 0.710000000000024 -1.37000039371714"
      rpy="1.5707963267949 0 0" />
    <parent
      link="base_link" />
    <child
      link="folk_left" />
    <axis
      xyz="0 0 0" />
  </joint>
  <link
    name="folk_right">
    <inertial>
      <origin
        xyz="2.02693118416455 1.38000039370852 0.275"
        rpy="0 0 0" />
      <mass
        value="0.524544939385207" />
      <inertia
        ixx="0.0132439651239293"
        ixy="-2.33948348458482E-16"
        ixz="-2.27031670422545E-19"
        iyy="0.0132439651530278"
        iyz="-4.95429230703405E-18"
        izz="4.21229162907784E-05" />
    </inertial>
    <visual>
      <origin
        xyz="0 0 0"
        rpy="0 0 0" />
      <geometry>
        <mesh
          filename="package://Macanum/meshes/folk_right.STL" />
      </geometry>
      <material
        name="">
        <color
          rgba="0.898039215686275 0.917647058823529 0.929411764705882 1" />
      </material>
    </visual>
    <collision>
      <origin
        xyz="0 0 0"
        rpy="0 0 0" />
      <geometry>
        <mesh
          filename="package://Macanum/meshes/folk_right.STL" />
      </geometry>
    </collision>
  </link>
  <joint
    name="folk_right_fixed"
    type="fixed">
    <origin
      xyz="-1.95943121112487 0.710000000000024 -1.37000039371705"
      rpy="1.5707963267949 0 0" />
    <parent
      link="base_link" />
    <child
      link="folk_right" />
    <axis
      xyz="0 0 0" />
  </joint>
</robot>